Workbook

Sheet Population Definitions
A1: Abbreviation | B1: Full Name | C1: Population type
A2: anc_hm | B2: Antenatal care: Humans | C2: anc_hm
A3: asx_hm | B3: Asphyxia: Humans | C3: asx_hm
A4: an_hm | B4: Anemia: Humans | C4: an_hm
A5: hm_hm | B5: Hemorrhage: Humans | C5: hm_hm
A6: msep_hm | B6: Maternal sepsis: Humans | C6: msep_hm
A7: preecl_hm | B7: Preeclampsia: Humans | C7: preecl_hm
A8: mnut_hm | B8: Maternal nutrition: Humans | C8: mnut_hm
A9: ol_hm | B9: Obstructed labor: Humans | C9: ol_hm
A10: oth_hm | B10: Other neonatal conditions: Humans | C10: oth_hm
A11: nsep_hm | B11: Neonatal sepsis: Humans | C11: nsep_hm
A12: pt_hm | B12: Preterm: Humans | C12: pt_hm
... A15: stunting_hm | B15: Stunting: Humans | C15: stunting_hm

Sheet Antenatal care
A1: Antenatal care: Number of pregnancies that occur annually | B1: Provenance | C1: Units | D1: Uncertainty | E1: Constant | G1: 2020 | H1: 2021 | I1: 2022 | J1: 2023 | K1: 2024 | L1: 2025 | M1: 2026 | N1: 2027 | O1: 2028 | P1: 2029 | Q1: 2030 | R1: 2031 | S1: 2032 | T1: 2033 | U1: 2034 | V1: 2035 | W1: 2036 | X1: 2037 | Y1: 2038 | Z1: 2039 | AA1: 2040 | AB1: 2041 | AC1: 2042 | AD1: 2043 | AE1: 2044 | AF1: 2045 | AG1: 2046 | AH1: 2047 | AI1: 2048 | AJ1: 2049 | AK1: 2050
A2: ='Population Definitions'!$A$2 -> anc_hm | B2: Framework-supplied default | C2: Number (per year) | E2: 35847026 | F2: OR
A3: #ignore | G3: 35847026 | H3: 35337491 | I3: 34884079 | J3: 34429389 | K3: 33889660 | L3: 33312424 | M3: 32731697 | N3: 32184866 | O3: 31673684 | P3: 31147745 | Q3: 30616659 | R3: 30090576 | S3: 29576646 | T3: 29096463 | U3: 28630815 | V3: 28167226 | W3: 27693145 | X3: 27188957 | Y3: 26702319 | Z3: 26230795 | AA3: 25770933 | AB3: 25317305 | AC3: 24862652 | AD3: 24413546 | AE3: 23961927 | AF3: 23518619 | AG3: 23097139 | AH3: 22715687 | AI3: 22344366 | AJ3: 21974021 | AK3: 21610495
A5: Antenatal care: Proportion of births with mortality due to all childbirth conditions not captured in any module | B5: Provenance | C5: Units | D5: Uncertainty | E5: Constant | G5: 2020 | H5: 2021 | I5: 2022 | J5: 2023 | K5: 2024 | L5: 2025
A6: ='[1]Population Definitions'!$A$2 -> anc_hm | B6: Framework-supplied default | C6: Proportion | E6: 0.0158697 | F6: OR
A8: Antenatal care: Life expectancy | B8: Provenance | C8: Units | D8: Uncertainty | E8: Constant | G8: 2020 | H8: 2021 | I8: 2022 | J8: 2023 | K8: 2024 | L8: 2025
A9: ='[2]Population Definitions'!$A$2 -> anc_hm | B9: https://data.un.org/Data.aspx?d=PopDiv&f=variableID%3A68 | C9: Number | E9: 85.6 | F9: OR
A11: Antenatal care: Average maternal age | B11: Provenance | C11: Units | D11: Uncertainty | E11: Constant | G11: 2020 | H11: 2021 | I11: 2022 | J11: 2023 | K11: 2024 | L11: 2025
A12: ='[2]Population Definitions'!$A$2 -> anc_hm | B12: https://population.un.org/dataportal/data/indicators/18/locations/1859,5504,1500,1501,5501,947/start/2024/end/2024/table/pivotbylocation?df=e8b7480d-00b9-4d06-b2da-e18447d1ab33 | C12: Number | E12: 28 | F12: OR
A14: Proportion that receive antenatal care at any point during pregnancy | B14: Provenance | C14: Units | D14: Uncertainty | E14: Constant | G14: 2020 | H14: 2021 | I14: 2022 | J14: 2023 | K14: 2024 | L14: 2025
A15: ='Population Definitions'!$A$2 -> anc_hm | B15: Framework-supplied default | C15: Proportion | E15: 0.95 | F15: OR
A17: Proportion receiving antenatal care in 1st trimester | B17: Provenance | C17: Units | D17: Uncertainty | E17: Constant | G17: 2020 | H17: 2021 | I17: 2022 | J17: 2023 | K17: 2024 | L17: 2025
A18: ='Population Definitions'!$A$2 -> anc_hm | B18: Framework-supplied default | C18: Proportion | F18: OR | G18: 0.55698013 | H18: 0.56812047 | I18: 0.5790495 | J18: 0.58975166 | K18: 0.6 | L18: 0.61166065 | M18: 0.62202709 | N18: 0.63260794 | O18: 0.64343611 | P18: 0.65452031 | Q18: 0.66616065 | R18: 0.67604001 | S18: 0.68542608 | T18: 0.69431129 | U18: 0.70273964 | V18: 0.71147242 | W18: 0.71878642 | X18: 0.7256895 | Y18: 0.73226099 | Z18: 0.73853715 | AA18: 0.74516776 | AB18: 0.75073852 | AC18: 0.75609847 | AD18: 0.76127757 | AE18: 0.76631482 | AF18: 0.77177703 | AG18: 0.77645454 | AH18: 0.78101836 | AI18: 0.78547802 | AJ18: 0.78984282 | AK18: 0.79462863
A20: Proportion receiving antenatal care in 2nd trimester | B20: Provenance | C20: Units | D20: Uncertainty | E20: Constant | G20: 2020 | H20: 2021 | I20: 2022 | J20: 2023 | K20: 2024 | L20: 2025 | M20: 2026 | N20: 2027 | O20: 2028 | P20: 2029 | Q20: 2030 | R20: 2031 | S20: 2032 | T20: 2033 | U20: 2034 | V20: 2035 | W20: 2036 | X20: 2037 | Y20: 2038 | Z20: 2039 | AA20: 2040 | AB20: 2041 | AC20: 2042 | AD20: 2043 | AE20: 2044 | AF20: 2045 | AG20: 2046 | AH20: 2047 | AI20: 2048 | AJ20: 2049 | AK20: 2050
A21: ='Population Definitions'!$A$2 -> anc_hm | B21: Framework-supplied default | C21: Proportion | F21: OR | G21: 0.88176636 | H21: 0.88756148 | I21: 0.89304342 | J21: 0.89820475 | K21: 0.90299327 | L21: 0.90824041 | M21: 0.9127481 | N21: 0.91719641 | O21: 0.92159672 | P21: 0.92594805 | Q21: 0.93034042 | R21: 0.93394321 | S21: 0.93725676 | T21: 0.94029701 | U21: 0.94309523 | V21: 0.94590886 | W21: 0.94820444 | X21: 0.95031653 | Y21: 0.95227884 | Z21: 0.95410945 | AA21: 0.95600201 | AB21: 0.95756182 | AC21: 0.95903273 | AD21: 0.96042637 | AE21: 0.96175614 | AF21: 0.96316514 | AG21: 0.9643518 | AH21: 0.96548898 | AI21: 0.96658097 | AJ21: 0.96763188 | AK21: 0.9687553
A23: Proportion receiving antenatal care in 3rd trimester | B23: Provenance | C23: Units | D23: Uncertainty | E23: Constant | G23: 2020 | H23: 2021 | I23: 2022 | J23: 2023 | K23: 2024 | L23: 2025 | M23: 2026 | N23: 2027 | O23: 2028 | P23: 2029 | Q23: 2030 | R23: 2031 | S23: 2032 | T23: 2033 | U23: 2034 | V23: 2035 | W23: 2036 | X23: 2037 | Y23: 2038 | Z23: 2039 | AA23: 2040 | AB23: 2041 | AC23: 2042 | AD23: 2043 | AE23: 2044 | AF23: 2045 | AG23: 2046 | AH23: 2047 | AI23: 2048 | AJ23: 2049 | AK23: 2050
A24: ='Population Definitions'!$A$2 -> anc_hm | B24: Framework-supplied default | C24: Proportion | F24: OR | G24: 0.90777728 | H24: 0.91284733 | I24: 0.91766387 | J24: 0.922195 | K24: 0.92637981 | L24: 0.93093194 | M24: 0.93483366 | N24: 0.93866358 | O24: 0.94243144 | P24: 0.94613565 | Q24: 0.94984119 | R24: 0.95286938 | S24: 0.9556379 | T24: 0.95816274 | U24: 0.96047281 | V24: 0.96277283 | W24: 0.96464451 | X24: 0.96635813 | Y24: 0.96794261 | Z24: 0.96941482 | AA24: 0.97091931 | AB24: 0.97215784 | AC24: 0.97332136 | AD24: 0.97441935 | AE24: 0.97546295 | AF24: 0.97655608 | AG24: 0.97747484 | AH24: 0.9783514 | AI24: 0.97918941 | AJ24: 0.97999178 | AK24: 0.98084281
A26: Antenatal care: Proportion of pregnancy loss for any reason 1st trimester | B26: Provenance | C26: Units | D26: Uncertainty | E26: Constant | G26: 2020 | H26: 2021 | I26: 2022 | J26: 2023 | K26: 2024 | L26: 2025
A27: ='Population Definitions'!$A$2 -> anc_hm | B27: Framework-supplied default | C27: Proportion | E27: 0.0225 | F27: OR
A29: Antenatal care: Proportion of pregnancy loss for any reason 2nd trimester | B29: Provenance | C29: Units | D29: Uncertainty | E29: Constant | G29: 2020 | H29: 2021 | I29: 2022 | J29: 2023 | K29: 2024 | L29: 2025
A30: ='Population Definitions'!$A$2 -> anc_hm | B30: Framework-supplied default | C30: Proportion | E30: 0.0225 | F30: OR
A32: Antenatal care: Proportion of pregnancy loss for any reason 3rd trimester | B32: Provenance | C32: Units | D32: Uncertainty | E32: Constant | G32: 2020 | H32: 2021 | I32: 2022 | J32: 2023 | K32: 2024 | L32: 2025
A33: ='Population Definitions'!$A$2 -> anc_hm | B33: Framework-supplied default | C33: Proportion | E33: 0.033 | F33: OR
A35: Antenatal care: Proportion of births at a referral facility not a result of risks detected via ultrasound (ie, those that have childbirth at a referral facility without a referral) | B35: Provenance | C35: Units | D35: Uncertainty | E35: Constant | G35: 2020 | H35: 2021 | I35: 2022 | J35: 2023 | K35: 2024 | L35: 2025 | M35: 2026 | N35: 2027 | O35: 2028 | P35: 2029 | Q35: 2030 | R35: 2031 | S35: 2032 | T35: 2033 | U35: 2034 | V35: 2035 | W35: 2036 | X35: 2037 | Y35: 2038 | Z35: 2039 | AA35: 2040 | AB35: 2041 | AC35: 2042 | AD35: 2043 | AE35: 2044 | AF35: 2045 | AG35: 2046 | AH35: 2047 | AI35: 2048 | AJ35: 2049 | AK35: 2050
A36: ='Population Definitions'!$A$2 -> anc_hm | B36: Framework-supplied default | C36: Proportion | F36: OR | G36: =G37-0.1415 -> 0.68045567 | H36: =H37-0.1415 -> 0.69044455 | I36: =I37-0.1415 -> 0.69974223 | J36: =J37-0.1415 -> 0.70849733 | K36: =K37-0.1415 -> 0.71654428 | L36: =L37-0.1415 -> 0.72556687 | M36: =M37-0.1415 -> 0.73316771 | N36: =N37-0.1415 -> 0.74067309 | ... AK36: =AK37-0.1415 -> 0.82272654
A37: #ignore | G37: 0.82195567 | H37: 0.83194455 | I37: 0.84124223 | J37: 0.84999733 | K37: 0.85804428 | L37: 0.86706687 | M37: 0.87466771 | N37: 0.88217309 | O37: 0.88958348 | P37: 0.89688524 | Q37: 0.90434072 | R37: 0.91029568 | S37: 0.91573081 | T37: 0.92067919 | U37: 0.92520112 | V37: 0.92977975 | W37: 0.93339437 | X37: 0.93669406 | Y37: 0.93973771 | Z37: 0.94255717 | AA37: 0.94549618 | AB37: 0.94782457 | AC37: 0.95000614 | AD37: 0.95206119 | AE37: 0.95401201 | AF37: 0.95613238 | AG37: 0.95784991 | AH37: 0.95948915 | AI37: 0.96105692 | AJ37: 0.96255899 | AK37: 0.96422654
A39: Antenatal care: Proportion of pregnant women attending ANC who received an ultrasound by 3rd trimester | B39: Provenance | C39: Units | D39: Uncertainty | E39: Constant | G39: 2020 | H39: 2021 | I39: 2022 | J39: 2023 | K39: 2024 | L39: 2025
A40: ='Population Definitions'!$A$2 -> anc_hm | B40: Framework-supplied default | C40: Proportion | E40: 0.234 | F40: OR

Sheet Asphyxia
A1: Asphyxia: Relative risk of stillbirth from obstructed labor | B1: Provenance | C1: Units | D1: Uncertainty | E1: Constant | G1: 2020 | H1: 2021 | I1: 2022 | J1: 2023 | K1: 2024 | L1: 2025
A2: ='Population Definitions'!$A$3 -> asx_hm | B2: Framework-supplied default | C2: Proportion | E2: 1.87 | F2: OR
A4: Asphyxia: Relative risk of stillbirth from maternal underweight | B4: Provenance | C4: Units | D4: Uncertainty | E4: Constant | G4: 2020 | H4: 2021 | I4: 2022 | J4: 2023 | K4: 2024 | L4: 2025
A5: ='Population Definitions'!$A$3 -> asx_hm | B5: Framework-supplied default | C5: Proportion | E5: 1.1 | F5: OR
A7: Asphyxia: Relative risk of stillbirth from maternal sepsis | B7: Provenance | C7: Units | D7: Uncertainty | E7: Constant | G7: 2020 | H7: 2021 | I7: 2022 | J7: 2023 | K7: 2024 | L7: 2025
A8: ='Population Definitions'!$A$3 -> asx_hm | B8: Framework-supplied default | C8: Proportion | E8: 1.58 | F8: OR
A10: Asphyxia: Reduction in stillbirth due to BEP | B10: Provenance | C10: Units | D10: Uncertainty | E10: Constant | G10: 2020 | H10: 2021 | I10: 2022 | J10: 2023 | K10: 2024 | L10: 2025
A11: ='Population Definitions'!$A$3 -> asx_hm | B11: Framework-supplied default | C11: Proportion | E11: 0.6 | F11: OR
A13: Asphyxia: Relative risk of stillbirth from early onset pre-eclampsia | B13: Provenance | C13: Units | D13: Uncertainty | E13: Constant | G13: 2020 | H13: 2021 | I13: 2022 | J13: 2023 | K13: 2024 | L13: 2025
A14: ='[3]Population Definitions'!$A$3 -> asx_hm | B14: Framework-supplied default | C14: Proportion | E14: 35 | F14: OR
A16: Asphyxia: Relative risk of stillbirth from late onset pre-eclampsia | B16: Provenance | C16: Units | D16: Uncertainty | E16: Constant | G16: 2020 | H16: 2021 | I16: 2022 | J16: 2023 | K16: 2024 | L16: 2025
A17: ='[3]Population Definitions'!$A$3 -> asx_hm | B17: Framework-supplied default | C17: Proportion | E17: 1.86 | F17: OR
A19: Asphyxia: Proportion of births that are stillbirth in the absence of risk factors | B19: Provenance | C19: Units | D19: Uncertainty | E19: Constant | G19: 2020 | H19: 2021 | I19: 2022 | J19: 2023 | K19: 2024 | L19: 2025
A20: ='Population Definitions'!$A$3 -> asx_hm | B20: Framework-supplied default | C20: Proportion | E20: 0.0139891 | F20: OR
A22: Proportion of obstructed labor cases that produce birth asphyxia | B22: Provenance | C22: Units | D22: Uncertainty | E22: Constant | G22: 2020 | H22: 2021 | I22: 2022 | J22: 2023 | K22: 2024 | L22: 2025
A23: ='Population Definitions'!$A$3 -> asx_hm | B23: Framework-supplied default | C23: Proportion | E23: 0.014943067 | F23: OR
A25: Relative risk of birth asphyxia from Obstructed labour | B25: Provenance | C25: Units | D25: Uncertainty | E25: Constant | G25: 2020 | H25: 2021 | I25: 2022 | J25: 2023 | K25: 2024 | L25: 2025
A26: ='Population Definitions'!$A$3 -> asx_hm | B26: Framework-supplied default | C26: Proportion | E26: 3.2 | F26: OR
A28: Efficacy of asphyxia treatment on mortality | B28: Provenance | C28: Units | D28: Uncertainty | E28: Constant | G28: 2020 | H28: 2021 | I28: 2022 | J28: 2023 | K28: 2024 | L28: 2025
A29: ='Population Definitions'!$A$3 -> asx_hm | B29: Framework-supplied default | C29: Proportion | E29: 0 | F29: OR
A31: Efficacy of asphyxia treatment on morbidity | B31: Provenance | C31: Units | D31: Uncertainty | E31: Constant | G31: 2020 | H31: 2021 | I31: 2022 | J31: 2023 | K31: 2024 | L31: 2025
A32: ='Population Definitions'!$A$3 -> asx_hm | B32: Framework-supplied default | C32: Proportion | E32: 0 | F32: OR
A34: Proportion of asphyxia that result in mortality due to encephalopathy at a referral facility | B34: Provenance | C34: Units | D34: Uncertainty | E34: Constant | G34: 2020 | H34: 2021 | I34: 2022 | J34: 2023 | K34: 2024 | L34: 2025
A35: ='Population Definitions'!$A$3 -> asx_hm | B35: Framework-supplied default | C35: Proportion | E35: 0.28 | F35: OR
A37: Proportion of asphyxia that result in mortality due to encephalopathy not at a referral facility | B37: Provenance | C37: Units | D37: Uncertainty | E37: Constant | G37: 2020 | H37: 2021 | I37: 2022 | J37: 2023 | K37: 2024 | L37: 2025
A38: ='Population Definitions'!$A$3 -> asx_hm | B38: Framework-supplied default | C38: Proportion | E38: 0.56 | F38: OR
A40: Asphyxia: Less severe disability due to encephalopathy (treated) (YLDs per case) | B40: Provenance | C40: Units | D40: Uncertainty | E40: Constant | G40: 2020 | H40: 2021 | I40: 2022 | J40: 2023 | K40: 2024 | L40: 2025
A41: ='Population Definitions'!$A$3 -> asx_hm | B41: Framework-supplied default | C41: Proportion | E41: 0.061 | F41: OR
A43: Asphyxia: Disability due to encephalopathy (YLDs per case) | B43: Provenance | C43: Units | D43: Uncertainty | E43: Constant | G43: 2020 | H43: 2021 | I43: 2022 | J43: 2023 | K43: 2024 | L43: 2025
A44: ='Population Definitions'!$A$3 -> asx_hm | B44: Framework-supplied default | C44: Proportion | E44: 2.17 | F44: OR
A46: Birth asphyxia incidence | B46: Provenance | C46: Units | D46: Uncertainty | E46: Constant | G46: 2020 | H46: 2021 | I46: 2022 | J46: 2023 | K46: 2024 | L46: 2025
A47: ='[1]Population Definitions'!$A$3 -> asx_hm | C47: Number | E47: 316904.71 | F47: OR
A49: Encephalopathy mortality due to birth asphyxia | B49: Provenance | C49: Units | D49: Uncertainty | E49: Constant | G49: 2020 | H49: 2021 | I49: 2022 | J49: 2023 | K49: 2024 | L49: 2025
A50: ='[1]Population Definitions'!$A$3 -> asx_hm | C50: Number | E50: 204537 | F50: OR
A52: Asphyxia: Stillbirth incidence | B52: Provenance | C52: Units | D52: Uncertainty | E52: Constant | G52: 2020 | H52: 2021 | I52: 2022 | J52: 2023 | K52: 2024 | L52: 2025
A53: ='[1]Population Definitions'!$A$3 -> asx_hm | C53: Number | E53: 544298 | F53: OR
A56: Asphyxia: Prevalence of maternal underweight | B56: Provenance | C56: Units | D56: Uncertainty | E56: Constant | G56: 2020 | H56: 2021 | I56: 2022 | J56: 2023 | K56: 2024 | L56: 2025
A57: ='[4]Population Definitions'!$A$3 -> asx_hm | B57: Framework-supplied default | C57: Proportion | E57: 0 | F57: OR
A59: Asphyxia: Prevalence of treated maternal underweight | B59: Provenance | C59: Units | D59: Uncertainty | E59: Constant | G59: 2020 | H59: 2021 | I59: 2022 | J59: 2023 | K59: 2024 | L59: 2025
A60: ='[4]Population Definitions'!$A$3 -> asx_hm | B60: Framework-supplied default | C60: Proportion | E60: 0 | F60: OR

Sheet Hemorrhage
A1: Relative reduction in mortality due to hemorrhage treatment | B1: Provenance | C1: Units | D1: Uncertainty | E1: Constant | G1: 2020 | H1: 2021 | I1: 2022 | J1: 2023 | K1: 2024 | L1: 2025
A2: ='Population Definitions'!$A$5 -> hm_hm | B2: Framework-supplied default | C2: Proportion | E2: 0 | F2: OR
A4: Relative risk of hemorrhage from non-severe anemia | B4: Provenance | C4: Units | D4: Uncertainty | E4: Constant | G4: 2020 | H4: 2021 | I4: 2022 | J4: 2023 | K4: 2024 | L4: 2025
A5: ='Population Definitions'!$A$5 -> hm_hm | B5: Framework-supplied default | C5: Proportion | E5: 1.49 | F5: OR
A7: Relative risk of hemorrhage from severe anemia | B7: Provenance | C7: Units | D7: Uncertainty | E7: Constant | G7: 2020 | H7: 2021 | I7: 2022 | J7: 2023 | K7: 2024 | L7: 2025
A8: ='Population Definitions'!$A$5 -> hm_hm | B8: Framework-supplied default | C8: Proportion | E8: 2.98 | F8: OR
A10: Relative risk of hemorrhage from obstructed labour | B10: Provenance | C10: Units | D10: Uncertainty | E10: Constant | G10: 2020 | H10: 2021 | I10: 2022 | J10: 2023 | K10: 2024 | L10: 2025
A11: ='Population Definitions'!$A$5 -> hm_hm | B11: Framework-supplied default | C11: Proportion | E11: 2.44 | F11: OR
A13: Proportion of childbirth in which hemorrhage will be imminent in the absence of risk factors | B13: Provenance | C13: Units | D13: Uncertainty | E13: Constant | G13: 2020 | H13: 2021 | I13: 2022 | J13: 2023 | K13: 2024 | L13: 2025
A14: ='Population Definitions'!$A$5 -> hm_hm | B14: Framework-supplied default | C14: Proportion | E14: 0.051014829 | F14: OR
A16: Hemorrhage: Proportion of pregnant women with a risk factor identifiable through ultrasound | B16: Provenance | C16: Units | D16: Uncertainty | E16: Constant | G16: 2020 | H16: 2021 | I16: 2022 | J16: 2023 | K16: 2024 | L16: 2025
A17: ='Population Definitions'!$A$5 -> hm_hm | B17: Framework-supplied default | C17: Proportion | E17: 0.57 | F17: OR
A19: Hemorrhage: Proportion of pregnant women with a risk factor identified through ultrasound | B19: Provenance | C19: Units | D19: Uncertainty | E19: Constant | G19: 2020 | H19: 2021 | I19: 2022 | J19: 2023 | K19: 2024 | L19: 2025
A20: ='Population Definitions'!$A$5 -> hm_hm | B20: Framework-supplied default | C20: Proportion | E20: 0.41 | F20: OR
A22: Hemorrhage: Proportion accepting referral | B22: Provenance | C22: Units | D22: Uncertainty | E22: Constant | G22: 2020 | H22: 2021 | I22: 2022 | J22: 2023 | K22: 2024 | L22: 2025 | M22: 2026 | N22: 2027 | O22: 2028 | P22: 2029 | Q22: 2030 | R22: 2031 | S22: 2032 | T22: 2033 | U22: 2034 | V22: 2035 | W22: 2036 | X22: 2037 | Y22: 2038 | Z22: 2039 | AA22: 2040
A23: ='Population Definitions'!$A$5 -> hm_hm | B23: Framework-supplied default | C23: Proportion | E23: 0.5 | F23: OR
A25: Proportion of childbirths with hemorrhage at a facility that result in maternal mortality in the absence of intervention | B25: Provenance | C25: Units | D25: Uncertainty | E25: Constant | G25: 2020 | H25: 2021 | I25: 2022 | J25: 2023 | K25: 2024 | L25: 2025
A26: ='Population Definitions'!$A$5 -> hm_hm | B26: Framework-supplied default | C26: Proportion | E26: 0.0041 | F26: OR
A28: Proportion of childbirths with hemorrhage at other locations that result in maternal mortality in the absence of intervention | B28: Provenance | C28: Units | D28: Uncertainty | E28: Constant | G28: 2020 | H28: 2021 | I28: 2022 | J28: 2023 | K28: 2024 | L28: 2025
A29: ='Population Definitions'!$A$5 -> hm_hm | B29: Framework-supplied default | C29: Proportion | E29: 0.01845 | F29: OR
A31: Disability weight due to hemorrhage at a referral facility (YLDs per case) | B31: Provenance | C31: Units | D31: Uncertainty | E31: Constant | G31: 2020 | H31: 2021 | I31: 2022 | J31: 2023 | K31: 2024 | L31: 2025
A32: ='Population Definitions'!$A$5 -> hm_hm | B32: Framework-supplied default | C32: Proportion | E32: 0.023 | F32: OR
A34: Disability weight due to hemorrhage in other facility (YLDs per case) | B34: Provenance | C34: Units | D34: Uncertainty | E34: Constant | G34: 2020 | H34: 2021 | I34: 2022 | J34: 2023 | K34: 2024 | L34: 2025
A35: ='Population Definitions'!$A$5 -> hm_hm | B35: Framework-supplied default | C35: Proportion | E35: 0.132 | F35: OR
A37: Hemorrhage: Number of incident cases | B37: Provenance | C37: Units | D37: Uncertainty | E37: Constant | G37: 2020 | H37: 2021 | I37: 2022 | J37: 2023 | K37: 2024 | L37: 2025
A38: ='[1]Population Definitions'!$A$5 -> hm_hm | C38: Number | E38: 3113735 | F38: OR
A40: Hemorrhage: Number of mortalities | B40: Provenance | C40: Units | D40: Uncertainty | E40: Constant | G40: 2020 | H40: 2021 | I40: 2022 | J40: 2023 | K40: 2024 | L40: 2025
A41: ='[1]Population Definitions'!$A$5 -> hm_hm | C41: Number | E41: 21506.5 | F41: OR

Sheet Anemia
A1: Relative risk of bleeding related anemia from hemorrhage | B1: Provenance | C1: Units | D1: Uncertainty | E1: Constant | G1: 2020 | H1: 2021 | I1: 2022 | J1: 2023 | K1: 2024 | L1: 2025
A2: ='Population Definitions'!$A$4 -> an_hm | B2: Framework-supplied default | C2: Proportion | E2: 10 | F2: OR
A4: Relative risk of bleeding related anemia from moderate or severe anemia during pregnancy | B4: Provenance | C4: Units | D4: Uncertainty | E4: Constant | G4: 2020 | H4: 2021 | I4: 2022 | J4: 2023 | K4: 2024 | L4: 2025
A5: ='Population Definitions'!$A$4 -> an_hm | B5: Framework-supplied default | C5: Proportion | E5: 5 | F5: OR
A7: Relative risk of bleeding related anemia from mild anemia during pregnancy | B7: Provenance | C7: Units | D7: Uncertainty | E7: Constant | G7: 2020 | H7: 2021 | I7: 2022 | J7: 2023 | K7: 2024 | L7: 2025
A8: ='Population Definitions'!$A$4 -> an_hm | B8: Framework-supplied default | C8: Proportion | E8: 2.5 | F8: OR
A10: Proportion of pregnant women that will experience anemia (total) | B10: Provenance | C10: Units | D10: Uncertainty | E10: Constant | G10: 2020 | H10: 2021 | I10: 2022 | J10: 2023 | K10: 2024 | L10: 2025
A11: ='Population Definitions'!$A$4 -> an_hm | B11: Framework-supplied default | C11: Proportion | E11: 0.763 | F11: OR
A13: Proportion of anemia cases in pregnant women that will be mild in the absence of risk factors | B13: Provenance | C13: Units | D13: Uncertainty | E13: Constant | G13: 2020 | H13: 2021 | I13: 2022 | J13: 2023 | K13: 2024 | L13: 2025
A14: ='Population Definitions'!$A$4 -> an_hm | B14: Framework-supplied default | C14: Proportion | E14: 0.45 | F14: OR
A16: Proportion of anemia cases in pregnant women that will be moderate | B16: Provenance | C16: Units | D16: Uncertainty | E16: Constant | G16: 2020 | H16: 2021 | I16: 2022 | J16: 2023 | K16: 2024 | L16: 2025
A17: ='Population Definitions'!$A$4 -> an_hm | B17: Framework-supplied default | C17: Proportion | E17: 0.53 | F17: OR
A19: Proportion of anemia cases in pregnant women that will be severe | B19: Provenance | C19: Units | D19: Uncertainty | E19: Constant | G19: 2020 | H19: 2021 | I19: 2022 | J19: 2023 | K19: 2024 | L19: 2025
A20: ='Population Definitions'!$A$4 -> an_hm | B20: Framework-supplied default | C20: Proportion | E20: 0.02 | F20: OR
A22: Proportion of pregnant women attending ANC in whom anemia will be diagnosed | B22: Provenance | C22: Units | D22: Uncertainty | E22: Constant | G22: 2020 | H22: 2021 | I22: 2022 | J22: 2023 | K22: 2024 | L22: 2025
A23: ='Population Definitions'!$A$4 -> an_hm | B23: Framework-supplied default | C23: Proportion | E23: 0.667 | F23: OR
A25: Proportion of mild anemia cases that are treated 1st trimester | B25: Provenance | C25: Units | D25: Uncertainty | E25: Constant | G25: 2020 | H25: 2021 | I25: 2022 | J25: 2023 | K25: 2024 | L25: 2025
A26: ='Population Definitions'!$A$4 -> an_hm | B26: Framework-supplied default | C26: Proportion | E26: 0 | F26: OR
A28: Proportion of moderate anemia cases mitigated to mild anemia via treatment after 3 months 1st trimester | B28: Provenance | C28: Units | D28: Uncertainty | E28: Constant | G28: 2020 | H28: 2021 | I28: 2022 | J28: 2023 | K28: 2024 | L28: 2025
A29: ='Population Definitions'!$A$4 -> an_hm | B29: Framework-supplied default | C29: Proportion | E29: 0 | F29: OR
A31: Proportion of severe anemia cases that are mitigated to moderate anemia via treatment after 3 months 1st trimester | B31: Provenance | C31: Units | D31: Uncertainty | E31: Constant | G31: 2020 | H31: 2021 | I31: 2022 | J31: 2023 | K31: 2024 | L31: 2025
A32: ='Population Definitions'!$A$4 -> an_hm | B32: Framework-supplied default | C32: Proportion | E32: 0 | F32: OR
A34: Proportion of mild anemia cases that are treated 2nd trimester | B34: Provenance | C34: Units | D34: Uncertainty | E34: Constant | G34: 2020 | H34: 2021 | I34: 2022 | J34: 2023 | K34: 2024 | L34: 2025
A35: ='Population Definitions'!$A$4 -> an_hm | B35: Framework-supplied default | C35: Proportion | E35: 0.05 | F35: OR
A37: Proportion of moderate anemia cases mitigated to mild anemia via treatment after 3 months 2nd trimester | B37: Provenance | C37: Units | D37: Uncertainty | E37: Constant | G37: 2020 | H37: 2021 | I37: 2022 | J37: 2023 | K37: 2024 | L37: 2025
A38: ='Population Definitions'!$A$4 -> an_hm | B38: Framework-supplied default | C38: Proportion | E38: 0.05 | F38: OR
A40: Proportion of severe anemia cases that are mitigated to moderate anemia via treatment after 3 months 2nd trimester | B40: Provenance | C40: Units | D40: Uncertainty | E40: Constant | G40: 2020 | H40: 2021 | I40: 2022 | J40: 2023 | K40: 2024 | L40: 2025
A41: ='Population Definitions'!$A$4 -> an_hm | B41: Framework-supplied default | C41: Proportion | E41: 0.05 | F41: OR
A43: Proportion with bleeding related anemia in the absence of risk factors | B43: Provenance | C43: Units | D43: Uncertainty | E43: Constant | G43: 2020 | H43: 2021 | I43: 2022 | J43: 2023 | K43: 2024 | L43: 2025
A44: ='Population Definitions'!$A$4 -> an_hm | B44: Framework-supplied default | C44: Proportion | E44: 0.1049562 | F44: OR
A46: Proportion of treated moderate anemia mitigated to mild anemia after 3 months postpartum | B46: Provenance | C46: Units | D46: Uncertainty | E46: Constant | G46: 2020 | H46: 2021 | I46: 2022 | J46: 2023 | K46: 2024 | L46: 2025
A47: ='Population Definitions'!$A$4 -> an_hm | B47: Framework-supplied default | C47: Proportion | E47: 0 | F47: OR
A49: Proportion of treated severe anemia mitigated to moderate anemia after 3 months postpartum | B49: Provenance | C49: Units | D49: Uncertainty | E49: Constant | G49: 2020 | H49: 2021 | I49: 2022 | J49: 2023 | K49: 2024 | L49: 2025
A50: ='Population Definitions'!$A$4 -> an_hm | B50: Framework-supplied default | C50: Proportion | E50: 0 | F50: OR
A52: Disability due to mild anemia (YLDs per case) | B52: Provenance | C52: Units | D52: Uncertainty | E52: Constant | G52: 2020 | H52: 2021 | I52: 2022 | J52: 2023 | K52: 2024 | L52: 2025
A53: ='Population Definitions'!$A$4 -> an_hm | B53: Framework-supplied default | C53: Number | E53: 0.003 | F53: OR
A55: Disability due to moderate anemia (YLDs per case) | B55: Provenance | C55: Units | D55: Uncertainty | E55: Constant | G55: 2020 | H55: 2021 | I55: 2022 | J55: 2023 | K55: 2024 | L55: 2025
A56: ='Population Definitions'!$A$4 -> an_hm | B56: Framework-supplied default | C56: Number | E56: 0.051 | F56: OR
A58: Disability due to severe anemia (YLDs per case) | B58: Provenance | C58: Units | D58: Uncertainty | E58: Constant | G58: 2020 | H58: 2021 | I58: 2022 | J58: 2023 | K58: 2024 | L58: 2025
A59: ='Population Definitions'!$A$4 -> an_hm | B59: Framework-supplied default | C59: Number | E59: 0.147 | F59: OR

Sheet Maternal sepsis
A1: Maternal sepsis: Maternal Azithromycin product coverage | B1: Provenance | C1: Units | D1: Uncertainty | E1: Constant | G1: 2020 | H1: 2021 | I1: 2022 | J1: 2023 | K1: 2024 | L1: 2025
A2: ='Population Definitions'!$A$6 -> msep_hm | B2: Framework-supplied default | C2: Proportion | E2: 0 | F2: OR
A4: Maternal sepsis: Product risk reduction on sepsis | B4: Provenance | C4: Units | D4: Uncertainty | E4: Constant | G4: 2020 | H4: 2021 | I4: 2022 | J4: 2023 | K4: 2024 | L4: 2025
A5: ='Population Definitions'!$A$6 -> msep_hm | B5: Framework-supplied default | C5: Proportion | E5: 0.84 | F5: OR
A7: Maternal sepsis: Sepsis risk in the absence of intervention | B7: Provenance | C7: Units | D7: Uncertainty | E7: Constant | G7: 2020 | H7: 2021 | I7: 2022 | J7: 2023 | K7: 2024 | L7: 2025
A8: ='Population Definitions'!$A$6 -> msep_hm | B8: Framework-supplied default | C8: Proportion | E8: 0.13566802 | F8: OR
A10: Maternal sepsis: Proportion of cases of sepsis that result in late mortality | B10: Provenance | C10: Units | D10: Uncertainty | E10: Constant | G10: 2020 | H10: 2021 | I10: 2022 | J10: 2023 | K10: 2024 | L10: 2025
A11: ='Population Definitions'!$A$6 -> msep_hm | B11: Framework-supplied default | C11: Proportion | E11: 0 | F11: OR
A13: Maternal sepsis: Proportion of cases of sepsis that result in mortality | B13: Provenance | C13: Units | D13: Uncertainty | E13: Constant | G13: 2020 | H13: 2021 | I13: 2022 | J13: 2023 | K13: 2024 | L13: 2025
A14: ='Population Definitions'!$A$6 -> msep_hm | B14: Framework-supplied default | C14: Proportion | E14: 1.21338e-05 | F14: OR
A16: Maternal sepsis: Post childbirth disability due to sepsis (YLDs per case) | B16: Provenance | C16: Units | D16: Uncertainty | E16: Constant | G16: 2020 | H16: 2021 | I16: 2022 | J16: 2023 | K16: 2024 | L16: 2025
A17: ='Population Definitions'!$A$6 -> msep_hm | B17: Framework-supplied default | C17: Number | E17: 0.004655 | F17: OR
A19: Maternal sepsis: Incident cases | B19: Provenance | C19: Units | D19: Uncertainty | E19: Constant | G19: 2020 | H19: 2021 | I19: 2022 | J19: 2023 | K19: 2024 | L19: 2025
A20: ='[1]Population Definitions'!$A$6 -> msep_hm | C20: Number | E20: 5495269.3 | F20: OR
A22: Maternal sepsis: Mortalities | B22: Provenance | C22: Units | D22: Uncertainty | E22: Constant | G22: 2020 | H22: 2021 | I22: 2022 | J22: 2023 | K22: 2024 | L22: 2025
A23: ='[1]Population Definitions'!$A$6 -> msep_hm | C23: Number | E23: 2797.6542 | F23: OR
A25: Maternal sepsis: Maternal Azithromycin impact on other neonatal conditions | B25: Provenance | C25: Units | D25: Uncertainty | E25: Constant | G25: 2020 | H25: 2021 | I25: 2022 | J25: 2023 | K25: 2024 | L25: 2025
A26: ='[5]Population Definitions'!$A$6 -> msep_hm | C26: Proportion | E26: 0.1 | F26: OR
A28: Maternal sepsis: Maternal Azithromycin impact on stillbirths | B28: Provenance | C28: Units | D28: Uncertainty | E28: Constant | G28: 2020 | H28: 2021 | I28: 2022 | J28: 2023 | K28: 2024 | L28: 2025
A29: ='[5]Population Definitions'!$A$6 -> msep_hm | C29: Proportion | E29: 0.2 | F29: OR
A31: Maternal sepsis: Maternal Azithromycin pregnancy coverage for births at a referral facility | B31: Provenance | C31: Units | D31: Uncertainty | E31: Constant | G31: 2020 | H31: 2021 | I31: 2022 | J31: 2023 | K31: 2024 | L31: 2025
A32: ='[5]Population Definitions'!$A$6 -> msep_hm | C32: Proportion | E32: 0 | F32: OR

Sheet Obstructed labor
A1: Obstructed labor: Proportion of childbirth in which obstructed labour will be imminent | B1: Provenance | C1: Units | D1: Uncertainty | E1: Constant | G1: 2020 | H1: 2021 | I1: 2022 | J1: 2023 | K1: 2024 | L1: 2025
A2: ='Population Definitions'!$A$9 -> ol_hm | B2: Framework-supplied default | C2: Proportion | E2: 0.062464527 | F2: OR
A4: Proportion of pregnant women with risk factor for obstructed labor identified through ultrasound accepting referral | B4: Provenance | C4: Units | D4: Uncertainty | E4: Constant | G4: 2020 | H4: 2021 | I4: 2022 | J4: 2023 | K4: 2024 | L4: 2025 | M4: 2026 | N4: 2027 | O4: 2028 | P4: 2029 | Q4: 2030 | R4: 2031 | S4: 2032 | T4: 2033 | U4: 2034 | V4: 2035 | W4: 2036 | X4: 2037 | Y4: 2038 | Z4: 2039 | AA4: 2040
A5: ='Population Definitions'!$A$9 -> ol_hm | B5: Framework-supplied default | C5: Proportion | E5: 0.75 | F5: OR | G5: 0.75 | H5: 0.75 | I5: 0.75 | J5: 0.78125 | K5: 0.8125 | L5: 0.84375 | M5: 0.875 | N5: 0.90625 | O5: 0.9375 | P5: 0.96875 | Q5: 1 | R5: 1 | S5: 1 | T5: 1 | U5: 1 | V5: 1 | W5: 1 | X5: 1 | Y5: 1 | Z5: 1 | AA5: 1
A7: Obstructed labor: Proportion of pregnant women with a risk factor for obstructed labour identifiable through ultrasound | B7: Provenance | C7: Units | D7: Uncertainty | E7: Constant | G7: 2020 | H7: 2021 | I7: 2022 | J7: 2023 | K7: 2024 | L7: 2025
A8: ='Population Definitions'!$A$9 -> ol_hm | B8: Framework-supplied default | C8: Proportion | E8: 0.9 | F8: OR
A10: Obstructed labor: Proportion of pregnant women with a risk factor for obstructed labour identified through ultrasound | B10: Provenance | C10: Units | D10: Uncertainty | E10: Constant | G10: 2020 | H10: 2021 | I10: 2022 | J10: 2023 | K10: 2024 | L10: 2025
A11: ='Population Definitions'!$A$9 -> ol_hm | B11: Framework-supplied default | C11: Proportion | E11: 0.21 | F11: OR
A13: Proportion of births at a referral facility that result in mortality due to obstructed labor | B13: Provenance | C13: Units | D13: Uncertainty | E13: Constant | G13: 2020 | H13: 2021 | I13: 2022 | J13: 2023 | K13: 2024 | L13: 2025
A14: ='Population Definitions'!$A$9 -> ol_hm | B14: IHME | C14: Proportion | E14: 0.0007302985 | F14: OR
A16: Proportion of births not at a referral facility that result in mortality due to obstructed labor | B16: Provenance | C16: Units | D16: Uncertainty | E16: Constant | G16: 2020 | H16: 2021 | I16: 2022 | J16: 2023 | K16: 2024 | L16: 2025
A17: ='Population Definitions'!$A$9 -> ol_hm | B17: Assuming 0.92 RF non-csection impact | C17: Proportion | E17: 0.00079380272 | F17: OR
A19: Obstructed labor: Proportion of obstructed labour births that require a c-section | B19: Provenance | C19: Units | D19: Uncertainty | E19: Constant | G19: 2020 | H19: 2021 | I19: 2022 | J19: 2023 | K19: 2024 | L19: 2025
A20: ='Population Definitions'!$A$9 -> ol_hm | B20: Framework-supplied default | C20: Proportion | E20: 1 | F20: OR
A22: Obstructed labor: C-section coverage | B22: Provenance | C22: Units | D22: Uncertainty | E22: Constant | G22: 2020 | H22: 2021 | I22: 2022 | J22: 2023 | K22: 2024 | L22: 2025
A23: ='Population Definitions'!$A$9 -> ol_hm | B23: Framework-supplied default | C23: Proportion | E23: 0.451679 | F23: OR
A25: Obstructed labor: Less severe disability due to obstructed labour in referral facility (DALYs per case) | B25: Provenance | C25: Units | D25: Uncertainty | E25: Constant | G25: 2020 | H25: 2021 | I25: 2022 | J25: 2023 | K25: 2024 | L25: 2025
A26: ='Population Definitions'!$A$9 -> ol_hm | B26: Framework-supplied default | C26: Proportion | E26: 0.033 | F26: OR
A28: Obstructed labor: Disability due to obstructed labour in other location (DALYs per case) | B28: Provenance | C28: Units | D28: Uncertainty | E28: Constant | G28: 2020 | H28: 2021 | I28: 2022 | J28: 2023 | K28: 2024 | L28: 2025
A29: ='Population Definitions'!$A$9 -> ol_hm | B29: Framework-supplied default | C29: Proportion | E29: 0.066 | F29: OR
A31: Obstructed labor: Incident cases | B31: Provenance | C31: Units | D31: Uncertainty | E31: Constant | G31: 2020 | H31: 2021 | I31: 2022 | J31: 2023 | K31: 2024 | L31: 2025
A32: ='Population Definitions'!$A$9 -> ol_hm | C32: Number | E32: 2530142.3 | F32: OR
A34: Deaths due to obstructed labor | B34: Provenance | C34: Units | D34: Uncertainty | E34: Constant | G34: 2020 | H34: 2021 | I34: 2022 | J34: 2023 | K34: 2024 | L34: 2025
A35: ='Population Definitions'!$A$9 -> ol_hm | C35: Number | E35: 3587.6392 | F35: OR
A37: Proportion of obstructed labor cases that will not result in stillbirth due to treatment | B37: Provenance | C37: Units | D37: Uncertainty | E37: Constant | G37: 2020 | H37: 2021 | I37: 2022 | J37: 2023 | K37: 2024 | L37: 2025
A38: ='Population Definitions'!$A$9 -> ol_hm | B38: Framework-supplied default | C38: Proportion | E38: 0 | F38: OR

Sheet Other neonatal conditions
A1: Other neonatal conditions: Proportion of childbirth in which other neonatal condition occurs in the absence of intervention | B1: Provenance | C1: Units | D1: Uncertainty | E1: Constant | G1: 2020 | H1: 2021 | I1: 2022 | J1: 2023 | K1: 2024 | L1: 2025
A2: ='Population Definitions'!$A$10 -> oth_hm | B2: Framework-supplied default | C2: Proportion | E2: 1 | F2: OR
A4: Proportion of other neonatal conditions that result in mortality | B4: Provenance | C4: Units | D4: Uncertainty | E4: Constant | G4: 2020 | H4: 2021 | I4: 2022 | J4: 2023 | K4: 2024 | L4: 2025
A5: ='Population Definitions'!$A$10 -> oth_hm | B5: Framework-supplied default | C5: Proportion | E5: 0.0018295114 | F5: OR
A7: Proportion of other neonatal conditions that result in disability | B7: Provenance | C7: Units | D7: Uncertainty | E7: Constant | G7: 2020 | H7: 2021 | I7: 2022 | J7: 2023 | K7: 2024 | L7: 2025
A8: ='Population Definitions'!$A$10 -> oth_hm | B8: Framework-supplied default | C8: Proportion | E8: 0 | F8: OR
A10: Other neonatal conditions: Incident cases | B10: Provenance | C10: Units | D10: Uncertainty | E10: Constant | G10: 2020 | H10: 2021 | I10: 2022 | J10: 2023 | K10: 2024 | L10: 2025
A11: ='Population Definitions'!$A$10 -> oth_hm | B11: Framework-supplied default | C11: Number | E11: 0 | F11: OR
A13: Other neonatal conditions: Mortalities | B13: Provenance | C13: Units | D13: Uncertainty | E13: Constant | G13: 2020 | H13: 2021 | I13: 2022 | J13: 2023 | K13: 2024 | L13: 2025
A14: ='Population Definitions'!$A$10 -> oth_hm | B14: Framework-supplied default | C14: Number | E14: 0 | F14: OR

Sheet Neonatal sepsis
A1: Relative risk of neonatal sepsis from maternal sepsis | B1: Provenance | C1: Units | D1: Uncertainty | E1: Constant | G1: 2020 | H1: 2021 | I1: 2022 | J1: 2023 | K1: 2024 | L1: 2025
A2: ='Population Definitions'!$A$11 -> nsep_hm | B2: Framework-supplied default | C2: Proportion | E2: 4.42 | F2: OR
A4: Neonatal sepsis: Proportion of preterm that is identified | B4: Provenance | C4: Units | D4: Uncertainty | E4: Constant | G4: 2020 | H4: 2021 | I4: 2022 | J4: 2023 | K4: 2024 | L4: 2025
A5: ='Population Definitions'!$A$11 -> nsep_hm | B5: Framework-supplied default | C5: Proportion | E5: 0.9 | F5: OR
A7: Efficacy of product for treatment of neonatal sepsis | B7: Provenance | C7: Units | D7: Uncertainty | E7: Constant | G7: 2020 | H7: 2021 | I7: 2022 | J7: 2023 | K7: 2024 | L7: 2025
A8: ='Population Definitions'!$A$11 -> nsep_hm | B8: Framework-supplied default | C8: Proportion | E8: 0 | F8: OR
A10: Proportion of childbirths in which neonatal sepsis occurs in preterm/SGA neonates in the absence of treatment in the absence of risk factors | B10: Provenance | C10: Units | D10: Uncertainty | E10: Constant | G10: 2020 | H10: 2021 | I10: 2022 | J10: 2023 | K10: 2024 | L10: 2025
A11: ='Population Definitions'!$A$11 -> nsep_hm | B11: Framework-supplied default | C11: Proportion | E11: 0.0170837 | F11: OR
A13: Proportion of childbirths in which neonatal sepsis occurs in term/AGA neonates in the absence of risk factors | B13: Provenance | C13: Units | D13: Uncertainty | E13: Constant | G13: 2020 | H13: 2021 | I13: 2022 | J13: 2023 | K13: 2024 | L13: 2025
A14: ='Population Definitions'!$A$11 -> nsep_hm | B14: Framework-supplied default | C14: Proportion | E14: =E11 -> 0.0170837 | F14: OR
A16: Neonatal sepsis mortality rate | B16: Provenance | C16: Units | D16: Uncertainty | E16: Constant | G16: 2020 | H16: 2021 | I16: 2022 | J16: 2023 | K16: 2024 | L16: 2025
A17: ='Population Definitions'!$A$11 -> nsep_hm | B17: Framework-supplied default | C17: Proportion | E17: 0.0510499 | F17: OR
A19: Proportion of cases of neonatal sepsis that result in morbidity | B19: Provenance | C19: Units | D19: Uncertainty | E19: Constant | G19: 2020 | H19: 2021 | I19: 2022 | J19: 2023 | K19: 2024 | L19: 2025
A20: ='Population Definitions'!$A$11 -> nsep_hm | B20: Framework-supplied default | C20: Proportion | E20: 0.961 | F20: OR
A22: Neonatal sepsis: Number of incident cases | B22: Provenance | C22: Units | D22: Uncertainty | E22: Constant | G22: 2020 | H22: 2021 | I22: 2022 | J22: 2023 | K22: 2024 | L22: 2025
A23: ='Population Definitions'!$A$11 -> nsep_hm | C23: Number | E23: 1732108.2 | F23: OR
A25: Number of childbirths that result in mortality due to neonatal sepsis | B25: Provenance | C25: Units | D25: Uncertainty | E25: Constant | G25: 2020 | H25: 2021 | I25: 2022 | J25: 2023 | K25: 2024 | L25: 2025
A26: ='Population Definitions'!$A$11 -> nsep_hm | B26: Framework-supplied default | C26: Number | E26: 55813.957 | F26: OR
A28: Neonatal sepsis: disability weight (DALYs per case) | B28: Provenance | C28: Units | D28: Uncertainty | E28: Constant | G28: 2020 | H28: 2021 | I28: 2022 | J28: 2023 | K28: 2024 | L28: 2025
A29: ='Population Definitions'!$A$11 -> nsep_hm | B29: Framework-supplied default | C29: Proportion | E29: 0.634 | F29: OR
A31: Neonatal sepsis: B. Infantis product efficacy on stunting | E31: Constant | G31: 2020 | H31: 2021 | I31: 2022 | J31: 2023 | K31: 2024 | L31: 2025
A32: nsep_hm | E32: 0 | F32: OR

Sheet Preterm
A1: Preterm: Proportion accepting referral | B1: Provenance | C1: Units | D1: Uncertainty | E1: Constant | G1: 2020 | H1: 2021 | I1: 2022 | J1: 2023 | K1: 2024 | L1: 2025 | M1: 2026 | N1: 2027 | O1: 2028 | P1: 2029 | Q1: 2030 | R1: 2031 | S1: 2032 | T1: 2033 | U1: 2034 | V1: 2035 | W1: 2036 | X1: 2037 | Y1: 2038 | Z1: 2039 | AA1: 2040
A2: ='Population Definitions'!$A$12 -> pt_hm | B2: Framework-supplied default | C2: Proportion | E2: 0.5 | F2: OR | G2: 0.5 | H2: 0.5 | I2: 0.5 | J2: 0.5625 | K2: 0.625 | L2: 0.6875 | M2: 0.75 | N2: 0.8125 | O2: 0.875 | P2: 0.9375 | Q2: 1 | R2: 1 | S2: 1 | T2: 1 | U2: 1 | V2: 1 | W2: 1 | X2: 1 | Y2: 1 | Z2: 1 | AA2: 1
A4: Reduction in preterm due to BEP | B4: Provenance | C4: Units | D4: Uncertainty | E4: Constant | G4: 2020 | H4: 2021 | I4: 2022 | J4: 2023 | K4: 2024 | L4: 2025 | M4: 2026 | N4: 2027 | O4: 2028 | P4: 2029 | Q4: 2030 | R4: 2031 | S4: 2032 | T4: 2033 | U4: 2034 | V4: 2035 | W4: 2036 | X4: 2037 | Y4: 2038 | Z4: 2039 | AA4: 2040
A5: ='Population Definitions'!$A$12 -> pt_hm | B5: Framework-supplied default | C5: Proportion | E5: 0.92 | F5: OR
A7: Preterm: Reduction in SGA due to BEP | B7: Provenance | C7: Units | D7: Uncertainty | E7: Constant | G7: 2020 | H7: 2021 | I7: 2022 | J7: 2023 | K7: 2024 | L7: 2025 | M7: 2026 | N7: 2027 | O7: 2028 | P7: 2029 | Q7: 2030 | R7: 2031 | S7: 2032 | T7: 2033 | U7: 2034 | V7: 2035 | W7: 2036 | X7: 2037 | Y7: 2038 | Z7: 2039 | AA7: 2040
A8: ='Population Definitions'!$A$12 -> pt_hm | B8: Framework-supplied default | C8: Proportion | E8: 0.92 | F8: OR
A10: Preterm: Proportion of term births that are SGA in the absence of risk factors | B10: Provenance | C10: Units | D10: Uncertainty | E10: Constant | G10: 2020 | H10: 2021 | I10: 2022 | J10: 2023 | K10: 2024 | L10: 2025
A11: ='Population Definitions'!$A$12 -> pt_hm | B11: Framework-supplied default | C11: Proportion | E11: 0.46031746 | F11: OR
A13: Proportion of preterm births that are SGA in the absence of risk factors | B13: Provenance | C13: Units | D13: Uncertainty | E13: Constant | G13: 2020 | H13: 2021 | I13: 2022 | J13: 2023 | K13: 2024 | L13: 2025
A14: ='Population Definitions'!$A$12 -> pt_hm | B14: Framework-supplied default | C14: Proportion | E14: 0.17777778 | F14: OR
A16: Proportion of births that are preterm in the absence of risk factors | B16: Provenance | C16: Units | D16: Uncertainty | E16: Constant | G16: 2020 | H16: 2021 | I16: 2022 | J16: 2023 | K16: 2024 | L16: 2025
A17: ='Population Definitions'!$A$12 -> pt_hm | B17: Framework-supplied default | C17: Proportion | E17: 0.13 | F17: OR
A19: Preterm: Relative risk of SGA from anemia | B19: Provenance | C19: Units | D19: Uncertainty | E19: Constant | G19: 2020 | H19: 2021 | I19: 2022 | J19: 2023 | K19: 2024 | L19: 2025
A20: ='Population Definitions'!$A$12 -> pt_hm | B20: Framework-supplied default | C20: Proportion | E20: 1.53 | F20: OR
A22: Preterm: Relative risk of SGA from maternal underweight | B22: Provenance | C22: Units | D22: Uncertainty | E22: Constant | G22: 2020 | H22: 2021 | I22: 2022 | J22: 2023 | K22: 2024 | L22: 2025
A23: ='Population Definitions'!$A$12 -> pt_hm | B23: Framework-supplied default | C23: Proportion | E23: 2 | F23: OR
A25: Relative risk of preterm from maternal underweight | B25: Provenance | C25: Units | D25: Uncertainty | E25: Constant | G25: 2020 | H25: 2021 | I25: 2022 | J25: 2023 | K25: 2024 | L25: 2025
A26: ='Population Definitions'!$A$12 -> pt_hm | B26: Framework-supplied default | C26: Proportion | E26: 1.3 | F26: OR
A28: Relative risk of preterm from maternal early onset pre-eclampsia | B28: Provenance | C28: Units | D28: Uncertainty | E28: Constant | G28: 2020 | H28: 2021 | I28: 2022 | J28: 2023 | K28: 2024 | L28: 2025
A29: ='Population Definitions'!$A$12 -> pt_hm | B29: Framework-supplied default | C29: Proportion | E29: 6.57 | F29: OR
A31: Relative risk of preterm from maternal late onset pre-eclampsia | B31: Provenance | C31: Units | D31: Uncertainty | E31: Constant | G31: 2020 | H31: 2021 | I31: 2022 | J31: 2023 | K31: 2024 | L31: 2025
A32: ='Population Definitions'!$A$12 -> pt_hm | B32: Framework-supplied default | C32: Proportion | E32: 2.44 | F32: OR
A34: Preterm: Relative risk of SGA from maternal early onset pre-eclampsia | B34: Provenance | C34: Units | D34: Uncertainty | E34: Constant | G34: 2020 | H34: 2021 | I34: 2022 | J34: 2023 | K34: 2024 | L34: 2025
A35: ='[6]Population Definitions'!$A$12 -> pt_hm | B35: Framework-supplied default | C35: Proportion | E35: 2.1 | F35: OR
A37: Preterm: Relative risk of SGA from maternal late onset pre-eclampsia | B37: Provenance | C37: Units | D37: Uncertainty | E37: Constant | G37: 2020 | H37: 2021 | I37: 2022 | J37: 2023 | K37: 2024 | L37: 2025
A38: ='[6]Population Definitions'!$A$12 -> pt_hm | B38: Framework-supplied default | C38: Proportion | E38: 1.1 | F38: OR
A40: Proportion of births that are preterm | B40: Provenance | C40: Units | D40: Uncertainty | E40: Constant | G40: 2020 | H40: 2021 | I40: 2022 | J40: 2023 | K40: 2024 | L40: 2025
A41: ='Population Definitions'!$A$12 -> pt_hm | B41: Framework-supplied default | C41: Proportion | E41: 0.10795898 | F41: OR
A43: Preterm: Proportion of term births that are SGA | B43: Provenance | C43: Units | D43: Uncertainty | E43: Constant | G43: 2020 | H43: 2021 | I43: 2022 | J43: 2023 | K43: 2024 | L43: 2025
A44: ='Population Definitions'!$A$12 -> pt_hm | B44: Framework-supplied default | C44: Proportion | E44: 0.46031746 | F44: OR
A46: Proportion of preterm births that are SGA | B46: Provenance | C46: Units | D46: Uncertainty | E46: Constant | G46: 2020 | H46: 2021 | I46: 2022 | J46: 2023 | K46: 2024 | L46: 2025
A47: ='Population Definitions'!$A$12 -> pt_hm | B47: Framework-supplied default | C47: Proportion | E47: 0.17777778 | F47: OR
A49: Proportion of childbirths that will be preterm sga which are identified through ultrasound | B49: Provenance | C49: Units | D49: Uncertainty | E49: Constant | G49: 2020 | H49: 2021 | I49: 2022 | J49: 2023 | K49: 2024 | L49: 2025
A50: ='Population Definitions'!$A$12 -> pt_hm | B50: Framework-supplied default | C50: Proportion | E50: 0.6 | F50: OR
A52: Proportion of childbirths that will be preterm aga which are identified through ultrasound | B52: Provenance | C52: Units | D52: Uncertainty | E52: Constant | G52: 2020 | H52: 2021 | I52: 2022 | J52: 2023 | K52: 2024 | L52: 2025
A53: ='Population Definitions'!$A$12 -> pt_hm | B53: Framework-supplied default | C53: Proportion | E53: 0.5 | F53: OR
A55: Preterm: Proportion of childbirths that will be term sga which are identified through ultrasound | B55: Provenance | C55: Units | D55: Uncertainty | E55: Constant | G55: 2020 | H55: 2021 | I55: 2022 | J55: 2023 | K55: 2024 | L55: 2025
A56: ='Population Definitions'!$A$12 -> pt_hm | B56: Framework-supplied default | C56: Proportion | E56: 0.6 | F56: OR
A58: Preterm: Proportion of childbirths that will be term aga which are identified through ultrasound | B58: Provenance | C58: Units | D58: Uncertainty | E58: Constant | G58: 2020 | H58: 2021 | I58: 2022 | J58: 2023 | K58: 2024 | L58: 2025
A59: ='Population Definitions'!$A$12 -> pt_hm | B59: Framework-supplied default | C59: Proportion | E59: 0.5 | F59: OR
...

Sheet RDS
A1: RDS: Proportion of cases of preterm that are identified | B1: Provenance | C1: Units | D1: Uncertainty | E1: Constant | G1: 2020 | H1: 2021 | I1: 2022 | J1: 2023 | K1: 2024 | L1: 2025
A2: ='Population Definitions'!$A$13 -> rds_hm | B2: Framework-supplied default | C2: Proportion | E2: 0.5 | F2: OR
A4: RDS risk in the absence of any interventions | B4: Provenance | C4: Units | D4: Uncertainty | E4: Constant | G4: 2020 | H4: 2021 | I4: 2022 | J4: 2023 | K4: 2024 | L4: 2025
A5: ='Population Definitions'!$A$13 -> rds_hm | B5: Framework-supplied default | C5: Proportion | E5: 0.342 | F5: OR
A7: RDS product efficacy | B7: Provenance | C7: Units | D7: Uncertainty | E7: Constant | G7: 2020 | H7: 2021 | I7: 2022 | J7: 2023 | K7: 2024 | L7: 2025
A8: ='Population Definitions'!$A$13 -> rds_hm | B8: Framework-supplied default | C8: Proportion | E8: 0 | F8: OR
A10: Proportion of childbirth in which RDS occurs given preterm identified | B10: Provenance | C10: Units | D10: Uncertainty | E10: Constant | G10: 2020 | H10: 2021 | I10: 2022 | J10: 2023 | K10: 2024 | L10: 2025
A11: ='Population Definitions'!$A$13 -> rds_hm | B11: Framework-supplied default | C11: Proportion | E11: =E5 -> 0.342 | F11: OR
A13: Proportion of childbirth in which RDS occurs given preterm not identified | B13: Provenance | C13: Units | D13: Uncertainty | E13: Constant | G13: 2020 | H13: 2021 | I13: 2022 | J13: 2023 | K13: 2024 | L13: 2025
A14: ='Population Definitions'!$A$13 -> rds_hm | B14: Framework-supplied default | C14: Proportion | E14: =E5 -> 0.342 | F14: OR
A16: Proportion of cases of RDS in which the neonate is less than 28 weeks gestational age | B16: Provenance | C16: Units | D16: Uncertainty | E16: Constant | G16: 2020 | H16: 2021 | I16: 2022 | J16: 2023 | K16: 2024 | L16: 2025
A17: ='Population Definitions'!$A$13 -> rds_hm | B17: Framework-supplied default | C17: Proportion | E17: 0.1 | F17: OR
A19: RDS mortality rate for cases at a referral facility less than 28 weeks | B19: Provenance | C19: Units | D19: Uncertainty | E19: Constant | G19: 2020 | H19: 2021 | I19: 2022 | J19: 2023 | K19: 2024 | L19: 2025
A20: ='Population Definitions'!$A$13 -> rds_hm | B20: Framework-supplied default | C20: Proportion | E20: 0.81 | F20: OR
A22: RDS mortality rate for cases at a other location less than 28 weeks | B22: Provenance | C22: Units | D22: Uncertainty | E22: Constant | G22: 2020 | H22: 2021 | I22: 2022 | J22: 2023 | K22: 2024 | L22: 2025
A23: ='Population Definitions'!$A$13 -> rds_hm | B23: Framework-supplied default | C23: Proportion | E23: 1 | F23: OR
A25: RDS mortality rate at referral in the absence of intervention greater than 28 weeks | B25: Provenance | C25: Units | D25: Uncertainty | E25: Constant | G25: 2020 | H25: 2021 | I25: 2022 | J25: 2023 | K25: 2024 | L25: 2025
A26: ='Population Definitions'!$A$13 -> rds_hm | B26: Framework-supplied default | C26: Proportion | E26: 0.376 | F26: OR
A28: Lung surfactant efficacy on RDS mortality | B28: Provenance | C28: Units | D28: Uncertainty | E28: Constant | G28: 2020 | H28: 2021 | I28: 2022 | J28: 2023 | K28: 2024 | L28: 2025
A29: ='Population Definitions'!$A$13 -> rds_hm | B29: Framework-supplied default | C29: Proportion | E29: 0 | F29: OR
A31: RDS mortality rate for cases at a other location greater than 28 weeks | B31: Provenance | C31: Units | D31: Uncertainty | E31: Constant | G31: 2020 | H31: 2021 | I31: 2022 | J31: 2023 | K31: 2024 | L31: 2025
A32: ='Population Definitions'!$A$13 -> rds_hm | B32: Framework-supplied default | C32: Proportion | E32: 0.922 | F32: OR
A34: Disability weight due to RDS morbidity | B34: Provenance | C34: Units | D34: Uncertainty | E34: Constant | G34: 2020 | H34: 2021 | I34: 2022 | J34: 2023 | K34: 2024 | L34: 2025
A35: ='Population Definitions'!$A$13 -> rds_hm | B35: Framework-supplied default | C35: Number | E35: 0.5474 | F35: OR

Sheet Wasting
A1: Proportion of births with severe wasting 6 to 18 months from birth in the absence of risk factors | B1: Provenance | C1: Units | D1: Uncertainty | E1: Constant | G1: 2020 | H1: 2021 | I1: 2022 | J1: 2023 | K1: 2024 | L1: 2025
A2: ='Population Definitions'!$A$14 -> wasting_hm | B2: Framework-supplied default | C2: Proportion | E2: 0.06 | F2: OR
A4: Proportion of births with moderate wasting 6 to 18 months from birth in the absence of risk factors | B4: Provenance | C4: Units | D4: Uncertainty | E4: Constant | G4: 2020 | H4: 2021 | I4: 2022 | J4: 2023 | K4: 2024 | L4: 2025
A5: ='Population Definitions'!$A$14 -> wasting_hm | B5: Framework-supplied default | C5: Proportion | E5: 0.18 | F5: OR
A7: Proportion of births with severe wasting 19 to 59 months from birth in the absence of risk factors | B7: Provenance | C7: Units | D7: Uncertainty | E7: Constant | G7: 2020 | H7: 2021 | I7: 2022 | J7: 2023 | K7: 2024 | L7: 2025
A8: ='Population Definitions'!$A$14 -> wasting_hm | C8: Proportion | E8: 0.04 | F8: OR
A10: Proportion of births with moderate wasting 19 to 59 months from birth in the absence of risk factors | B10: Provenance | C10: Units | D10: Uncertainty | E10: Constant | G10: 2020 | H10: 2021 | I10: 2022 | J10: 2023 | K10: 2024 | L10: 2025
A11: ='Population Definitions'!$A$14 -> wasting_hm | C11: Proportion | E11: 0.15 | F11: OR
A13: Relative risk of wasting from maternal underweight | B13: Provenance | C13: Units | D13: Uncertainty | E13: Constant | G13: 2020 | H13: 2021 | I13: 2022 | J13: 2023 | K13: 2024 | L13: 2025
A14: ='Population Definitions'!$A$14 -> wasting_hm | B14: Framework-supplied default | C14: Proportion | E14: 1.5 | F14: OR
A16: Relative risk of wasting from SGA | B16: Provenance | C16: Units | D16: Uncertainty | E16: Constant | G16: 2020 | H16: 2021 | I16: 2022 | J16: 2023 | K16: 2024 | L16: 2025
A17: ='Population Definitions'!$A$14 -> wasting_hm | B17: Framework-supplied default | C17: Proportion | E17: 2.36 | F17: OR
A19: Relative risk of wasting from preterm | B19: Provenance | C19: Units | D19: Uncertainty | E19: Constant | G19: 2020 | H19: 2021 | I19: 2022 | J19: 2023 | K19: 2024 | L19: 2025
A20: ='Population Definitions'!$A$14 -> wasting_hm | B20: Framework-supplied default | C20: Proportion | E20: 1.55 | F20: OR
A22: Relative risk of wasting from preterm SGA | B22: Provenance | C22: Units | D22: Uncertainty | E22: Constant | G22: 2020 | H22: 2021 | I22: 2022 | J22: 2023 | K22: 2024 | L22: 2025
A23: ='Population Definitions'!$A$14 -> wasting_hm | B23: Framework-supplied default | C23: Proportion | E23: 2.36 | F23: OR
A25: Efficacy of underweight treatment on wasting occurrence | B25: Provenance | C25: Units | D25: Uncertainty | E25: Constant | G25: 2020 | H25: 2021 | I25: 2022 | J25: 2023 | K25: 2024 | L25: 2025
A26: ='Population Definitions'!$A$14 -> wasting_hm | B26: Framework-supplied default | C26: Proportion | E26: 0 | F26: OR
A28: Efficacy of wasting treatment on hospitalized wasting mortality 6 to 18 months | B28: Provenance | C28: Units | D28: Uncertainty | E28: Constant | G28: 2020 | H28: 2021 | I28: 2022 | J28: 2023 | K28: 2024 | L28: 2025
A29: ='Population Definitions'!$A$14 -> wasting_hm | B29: Framework-supplied default | C29: Proportion | E29: 0 | F29: OR
A31: Efficacy of wasting treatment on community based wasting mortality 6 to 18 months | B31: Provenance | C31: Units | D31: Uncertainty | E31: Constant | G31: 2020 | H31: 2021 | I31: 2022 | J31: 2023 | K31: 2024 | L31: 2025
A32: ='Population Definitions'!$A$14 -> wasting_hm | B32: Framework-supplied default | C32: Proportion | E32: 0 | F32: OR
A34: Efficacy of wasting treatment on hospitalized wasting morbidity 6 to 18 months | B34: Provenance | C34: Units | D34: Uncertainty | E34: Constant | G34: 2020 | H34: 2021 | I34: 2022 | J34: 2023 | K34: 2024 | L34: 2025
A35: ='Population Definitions'!$A$14 -> wasting_hm | B35: Framework-supplied default | C35: Proportion | E35: 0 | F35: OR
A37: Efficacy of wasting treatment on community wasting morbidity 6 to 18 months | B37: Provenance | C37: Units | D37: Uncertainty | E37: Constant | G37: 2020 | H37: 2021 | I37: 2022 | J37: 2023 | K37: 2024 | L37: 2025
A38: ='Population Definitions'!$A$14 -> wasting_hm | B38: Framework-supplied default | C38: Proportion | E38: 0 | F38: OR
A40: Efficacy of wasting treatment on hospitalized wasting mortality 19 to 59 months | B40: Provenance | C40: Units | D40: Uncertainty | E40: Constant | G40: 2020 | H40: 2021 | I40: 2022 | J40: 2023 | K40: 2024 | L40: 2025
A41: ='Population Definitions'!$A$14 -> wasting_hm | B41: Framework-supplied default | C41: Proportion | E41: 0 | F41: OR
A43: Efficacy of wasting treatment on community wasting mortality 19 to 59 months | B43: Provenance | C43: Units | D43: Uncertainty | E43: Constant | G43: 2020 | H43: 2021 | I43: 2022 | J43: 2023 | K43: 2024 | L43: 2025
A44: ='Population Definitions'!$A$14 -> wasting_hm | B44: Framework-supplied default | C44: Proportion | E44: 0 | F44: OR
A46: Efficacy of wasting treatment on hospitalized wasting morbidity 19 to 59 months | B46: Provenance | C46: Units | D46: Uncertainty | E46: Constant | G46: 2020 | H46: 2021 | I46: 2022 | J46: 2023 | K46: 2024 | L46: 2025
A47: ='Population Definitions'!$A$14 -> wasting_hm | B47: Framework-supplied default | C47: Proportion | E47: 0 | F47: OR
A49: Efficacy of wasting treatment on community wasting morbidity 19 to 59 months | B49: Provenance | C49: Units | D49: Uncertainty | E49: Constant | G49: 2020 | H49: 2021 | I49: 2022 | J49: 2023 | K49: 2024 | L49: 2025
A50: ='Population Definitions'!$A$14 -> wasting_hm | B50: Framework-supplied default | C50: Proportion | E50: 0 | F50: OR
A52: Efficacy of treatment on wasting relapse | B52: Provenance | C52: Units | D52: Uncertainty | E52: Constant | G52: 2020 | H52: 2021 | I52: 2022 | J52: 2023 | K52: 2024 | L52: 2025
A53: ='Population Definitions'!$A$14 -> wasting_hm | B53: Framework-supplied default | C53: Proportion | E53: 0 | F53: OR
A55: Wasting: Proportion of births that are underweight 8 days to 5 months in the absence of risk factors | B55: Provenance | C55: Units | D55: Uncertainty | E55: Constant | G55: 2020 | H55: 2021 | I55: 2022 | J55: 2023 | K55: 2024 | L55: 2025
A56: ='Population Definitions'!$A$14 -> wasting_hm | B56: Framework-supplied default | C56: Proportion | E56: 0.33 | F56: OR
A58: Proportion of births that result in prolonged wasting 8 days to 5 months without intervention | B58: Provenance | C58: Units | D58: Uncertainty | E58: Constant | G58: 2020 | H58: 2021 | I58: 2022 | J58: 2023 | K58: 2024 | L58: 2025
A59: ='Population Definitions'!$A$14 -> wasting_hm | B59: Framework-supplied default | C59: Proportion | E59: 1 | F59: OR
...

Sheet Stunting
A1: Proportion of childbirths that result in stunting in the absence of a risk factors | B1: Provenance | C1: Units | D1: Uncertainty | E1: Constant | G1: 2020 | H1: 2021 | I1: 2022 | J1: 2023 | K1: 2024 | L1: 2025
A2: ='Population Definitions'!$A$15 -> stunting_hm | B2: Ki stunting rally results | C2: Proportion | E2: 0.11829923 | F2: OR
A4: Relative risk of stunting from maternal underweight | B4: Provenance | C4: Units | D4: Uncertainty | E4: Constant | G4: 2020 | H4: 2021 | I4: 2022 | J4: 2023 | K4: 2024 | L4: 2025
A5: ='Population Definitions'!$A$15 -> stunting_hm | B5: Framework-supplied default | C5: Proportion | E5: 1.25 | F5: OR
A7: Relative risk of stunting from preterm | B7: Provenance | C7: Units | D7: Uncertainty | E7: Constant | G7: 2020 | H7: 2021 | I7: 2022 | J7: 2023 | K7: 2024 | L7: 2025
A8: ='[6]Population Definitions'!$A$15 -> stunting_hm | B8: Framework-supplied default | C8: Proportion | E8: 2 | F8: OR
A10: Relative risk of stunting from SGA | B10: Provenance | C10: Units | D10: Uncertainty | E10: Constant | G10: 2020 | H10: 2021 | I10: 2022 | J10: 2023 | K10: 2024 | L10: 2025
A11: ='[6]Population Definitions'!$A$15 -> stunting_hm | B11: Framework-supplied default | C11: Proportion | E11: 2 | F11: OR
A13: Disability due to stunting (lifetime YLDs per infant) | B13: Provenance | C13: Units | D13: Uncertainty | E13: Constant | G13: 2020 | H13: 2021 | I13: 2022 | J13: 2023 | K13: 2024 | L13: 2025
