Workbook

Sheet Program targeting
C1: Targeted to (populations) | R1: Targeted to (compartments)
A2: Abbreviation | B2: Display name | C2: Antenatal care: Humans | D2: Asphyxia: Humans | E2: Anemia: Humans | F2: Hemorrhage: Humans | G2: Maternal sepsis: Humans | H2: Preeclampsia: Humans | I2: Maternal nutrition: Humans | J2: Obstructed labor: Humans | K2: Other neonatal conditions: Humans | L2: Neonatal sepsis: Humans | M2: Preterm: Humans | N2: RDS: Humans | O2: Wasting: Humans | P2: Stunting: Humans | R2: Antenatal care: ANC contacts 1st trimester | S2: Antenatal care: No ANC contacts 1st trimester | T2: Antenatal care: Pregnancy loss 1st trimester | U2: Antenatal care: Pregnant 2nd trimester | V2: Antenatal care: Pregnancy loss 2nd trimester | W2: Antenatal care: Pregnant 3rd trimester | X2: Antenatal care: Pregnancy loss 3rd trimester | Y2: Antenatal care: Birth at referral facility | Z2: Antenatal care: Birth at other location | AA2: Asphyxia: Stillbirth occurs | AB2: Junction: Outcome for birth asphyxia at a referral facility | AC2: Healthy with respect to birth asphyxia before corrections | AD2: Birth asphyxia without encephalopathy before corrections | AE2: Asphyxia: Less severe disability due to encephalopathy before corrections | AF2: Asphyxia: Disability due to encephalopathy before corrections | AG2: Death due to encephalopathy (resulting from birth asphyxia) before corrections | AH2: Healthy with respect to birth asphyxia | AI2: Birth asphyxia without encephalopathy | AJ2: Asphyxia: Less severe disability due to encephalopathy | AK2: Asphyxia: Disability due to encephalopathy | AL2: Death due to encephalopathy (resulting from birth asphyxia) | AM2: Asphyxia: Other mortality sink | AN2: Junction anemia occurs during pregnancy | AO2: Junction proportion of identified mild anemia mitigated to healthy in 1st trimester | AP2: Junction proportion of identified moderate anemia mitigated to mild anemia in 1st trimester | AQ2: Junction proportion of identified severe anemia mitigated to moderate anemia in 1st trimester | AR2: Healthy with respect to anemia at the end of 1st trimester before corrections | AS2: Mild anemia at the end of 1st trimester before corrections | AT2: Moderate anemia at the end of 1st trimester before corrections | AU2: Severe anemia at the end of 1st trimester before corrections | AV2: Anemia: Junction non-naïve healthy population 1st trimester (for targeting) | AW2: Junction proportion of mild anemia identified in 2nd trimester | AX2: Junction proportion of moderate anemia identified in 2nd trimester | AY2: Junction proportion of severe anemia identified in 2nd trimester | AZ2: Junction proportion of identified mild anemia mitigated to healthy in 2nd trimester | BA2: Junction proportion of identified moderate anemia mitigated to mild anemia in 2nd trimester | BB2: Junction proportion of identified severe anemia mitigated to moderate anemia in 2nd trimester | BC2: Healthy with respect to anemia at the end of 2nd trimester before corrections | BD2: Mild anemia at the end of 2nd trimester before corrections | BE2: Moderate anemia at the end of 2nd trimester before corrections | BF2: Severe anemia at the end of 2nd trimester before corrections | BG2: Healthy with respect to anemia at the end of 3rd trimester before corrections | BH2: Mild anemia at the end of 3rd trimester before corrections | BI2: Moderate anemia at the end of 3rd trimester before corrections | BJ2: Severe anemia at the end of 3rd trimester before corrections | BK2: Junction: proportion of identified moderate anemia mitigated to mild anemia post-partum | BL2: Junction: proportion of identified severe anemia mitigated to moderate anemia post-partum | BM2: Healthy with respect to anemia at three months post-partum before corrections | BN2: Disability due to mild anemia at three months post-partum before corrections | BO2: Disability due to moderate anemia at three months post-partum before corrections | BP2: Disability due to severe anemia at three months post-partum before corrections | BQ2: Anemia: No longer pregnant due to maternal mortality or other pregnancy loss | BR2: Anemia: Maternal mortality due to other causes during three months post-partum | BS2: Healthy with respect to anemia at three months post-partum | BT2: Disability due to mild anemia at three months post-partum | BU2: Disability due to moderate anemia at three months post-partum | BV2: Disability due to severe anemia at three months post-partum | BW2: Junction: Outcome of hemorrhage occurring at a referral facility | BX2: Junction: Outcome of hemorrhage occurring at an other location | BY2: Healthy with respect to hemorrhage before corrections | BZ2: Less severe disability due to hemorrhage before corrections | CA2: Disability due to hemorrhage before corrections | CB2: Death due to hemorrhage before corrections | CC2: Healthy with respect to hemorrhage | CD2: Less severe disability due to hemorrhage | CE2: Disability due to hemorrhage | CF2: Death due to hemorrhage | CG2: Hemorrhage: Death due to other condition | CH2: Maternal sepsis: Junction: attends ANC and is targeted by AzPregnancy | CI2: Maternal sepsis: Junction: Sepsis occurs at a referral facility | CJ2: Healthy with respect to maternal sepsis naïve calculation | CK2: Lesser disability due to maternal sepsis naïve calculation | CL2: Disability due to maternal sepsis naïve calculation | CM2: Mortality due to maternal sepsis naïve calculation | CN2: Healthy with respect to maternal sepsis | CO2: Lesser disability due to maternal sepsis | CP2: Disability due to maternal sepsis | CQ2: Mortality due to maternal sepsis | CR2: Maternal sepsis: Mortality due to other causes | CS2: Preeclampsia mortality | CT2: Preeclampsia: Junction: Pre-eclampsia occurs | CU2: Preeclampsia: Healthy with respect to pre-eclampsia 1st trimester (naïve) | CV2: Preeclampsia: Pre-eclampsia averted due to prevention treatment (naïve) | CW2: Preeclampsia: Pre-eclampsia occurs during pregnancy (early or late) | CX2: Preeclampsia: Junction: Early onset pre-eclampsia occurs given low risk of pre-eclampsia 2nd trimester | CY2: Preeclampsia: Junction: Early onset Pre-eclampsia treated 2nd trimester | CZ2: Preeclampsia: Healthy with respect to pre-eclampsia 2nd trimester (naïve) | DA2: Preeclampsia: Pre-eclampsia averted due to prevention treatment after 2nd trimester (naïve) | DB2: Preeclampsia: Late onset pre-eclampsia will occur after 2nd trimester (naïve) | DC2: Preeclampsia: Early onset pre-eclampsia treated 2nd trimester (naïve) | DD2: Preeclampsia: Early onset pre-eclampsia not treated 2nd trimester (naïve) | DE2: Preeclampsia: Early onset pre-eclampsia mortality 2nd trimester (naïve) | DF2: Preeclampsia: Junction: Severe late onset Pre-eclampsia treated 3rd trimester | DG2: Preeclampsia: Junction: non_severe late onset Pre-eclampsia treated 3rd trimester | DH2: Preeclampsia: Healthy with respect to pre-eclampsia 3rd trimester (naïve) | DI2: Preeclampsia: Pre-eclampsia averted 3rd trimester (naïve) | DJ2: Preeclampsia: Late onset pre-eclampsia treated 3rd trimester (naïve) | DK2: Preeclampsia: Late onset pre-eclampsia not treated 3rd trimester (naïve) | DL2: Preeclampsia: Late onset pre-eclampsia mortality 3rd trimester (naïve) | DM2: Preeclampsia: Early onset pre-eclampsia treated 3rd trimester (naïve) | DN2: Preeclampsia: Early onset pre-eclampsia not treated 3rd trimester (naïve) | DO2: Preeclampsia: Healthy with respect to pre-eclampsia 3rd trimester | DP2: Preeclampsia: Pre-eclampsia averted 3rd trimester | DQ2: Preeclampsia: Late onset pre-eclampsia treated 3rd trimester | DR2: Preeclampsia: Late onset pre-eclampsia not treated 3rd trimester | DS2: Preeclampsia: Late onset pre-eclampsia mortality 3rd trimester | DT2: Preeclampsia: Early onset pre-eclampsia treated 3rd trimester | DU2: Preeclampsia: Early onset pre-eclampsia not treated 3rd trimester | DV2: Maternal nutrition: Junction: treated with nutrient supplement | DW2: Maternal nutrition: Healthy with respect to childbirth naïve | DX2: Maternal nutrition: Healthy with respect to childbirth | DY2: Junction: Outcome of obstructed labor occurring at a referral facility | DZ2: Obstructed labor: Junction: Junction for computing c-section costs | EA2: Healthy with respect to obstructed labor naïve calculation | EB2: Less severe disability due to obstructed labor naïve calculation | EC2: Disability due to obstructed labor naïve calculation | ED2: Death due to obstructed labor at a referral facility naïve calculation | EE2: Death due to obstructed labor not at a referral facility naïve calculation | EF2: Healthy with respect to obstructed labor | EG2: Less severe disability due to obstructed labor | EH2: Disability due to obstructed labor | EI2: Death due to obstructed labor at a referral facility | EJ2: Death due to obstructed labor not at a referral facility | EK2: Obstructed labor: Mortality due to other causes | EL2: Other neonatal conditions: Stillbirth occurs | EM2: Other neonatal conditions: Healthy with respect to other neonatal condition | EN2: Other neonatal conditions: Other neonatal condition occurs, no disability occurs | EO2: Other neonatal conditions: Other neonatal condition occurs, disability occurs | EP2: Other neonatal conditions: Mortality due to other neonatal_condition | EQ2: Other neonatal conditions: Mortality due to other causes captured in model sink | ER2: Neonatal sepsis: Stillbirth occurs | ES2: Junction: Neonatal sepsis occurs for an identified preterm/SGA neonate | ET2: Healthy with respect to neonatal sepsis before other mortality occurs | EU2: Neonatal sepsis without disability before other mortality occurs | EV2: Disability due to neonatal sepsis before other mortality occurs | EW2: Death due to neonatal sepsis before other mortality occurs | EX2: Healthy with respect to neonatal sepsis | EY2: Neonatal sepsis without disability | EZ2: Disability due to neonatal sepsis | FA2: Death due to neonatal sepsis | FB2: Junction: Referral facility outcome for preterm SGA | FC2: Junction: Other location outcome for preterm SGA | FD2: Junction: Referral facility outcome for preterm AGA | FE2: Junction: Other location outcome for preterm AGA | FF2: Preterm: Junction: Referral facility outcome for term SGA | FG2: Preterm: Junction: Other location outcome for term SGA | FH2: Preterm: Junction: Referral facility outcome for term AGA | FI2: Preterm: Junction: Other location outcome for term AGA | FJ2: Healthy with respect to preterm and SGA before corrections | FK2: Mortality due to preterm birth before corrections | FL2: Disbaility due to preterm SGA birth before corrections | FM2: Preterm SGA with no disability before corrections | FN2: Disbaility due to preterm birth before corrections | FO2: Preterm with no disability before corrections | FP2: Preterm: Mortality due to SGA birth before corrections | FQ2: Preterm: Disbaility due to SGA birth before corrections | FR2: Preterm: SGA with no disability before corrections | FS2: Preterm: Mortality due to other causes | FT2: Healthy with respect to preterm and SGA | FU2: Mortality due to preterm birth | FV2: Disbaility due to preterm SGA birth | FW2: Preterm SGA with no disability | FX2: Disbaility due to preterm birth | FY2: Preterm with no disability | FZ2: Preterm: Mortality due to SGA birth | GA2: Preterm: Disbaility due to SGA birth | GB2: Preterm: SGA with no disability | GC2: RDS: Stillbirth occurs | GD2: Junction: RDS occurs, preterm identified | GE2: Junction: RDS outcome for neonate greater than 28 weeks at other location | GF2: Healthy with respect to RDS before corrections | GG2: RDS: Birth asphyxia without encephalopathy before corrections | GH2: Death due to RDS (resulting from birth asphyxia) before corrections | GI2: Healthy with respect to RDS | GJ2: RDS: Birth asphyxia without encephalopathy | GK2: Death due to RDS (resulting from birth asphyxia) | GL2: RDS: Other mortality | GM2: Wasting: Other mortality | GN2: Junction: Outcome for those with wasting 8 days to 5 months from birth | GO2: Healthy, but at risk of wasting 8 days to 5 months from birth | GP2: Morbidity due to wasting, at risk of wasting 8 days to 5 months from birth | GQ2: Wasting: Less severe disability due to encephalopathy 8 days to 5 months from birth | GR2: Junction: Mortality due to hospitalized severe wasting 6 to 18 months from birth | GS2: Junction: Mortality due to hospitalized moderate wasting 6 to 18 months from birth | GT2: Junction: Mortality due to no illness or community based severe wasting 6 to 18 months from birth | GU2: Junction: Mortality due to no illness or community based moderate wasting 6 to 18 months from birth | GV2: Healthy, but at risk of wasting 6 to 18 months from birth | GW2: Morbidity due to wasting, at risk of wasting 6 to 18 months from birth | GX2: Mortality due to wasting 6 to 18 months from birth | GY2: Junction: Mortality due to hospitalized severe wasting 19 to 59 months from birth | GZ2: Junction: Mortality due to hospitalized moderate wasting 19 to 59 months from birth | HA2: Junction: Mortality due to no illness or community based severe wasting 19 to 59 months from birth | HB2: Junction: Mortality due to no illness or community based moderate wasting 19 to 59 months from birth | HC2: Healthy, but at risk of wasting 19 and 59 months from birth | HD2: Morbidity due to wasting, at risk of wasting 19 and 59 months from birth | HE2: Mortality due to wasting 19 to 59 months from births | HF2: Stunting: Stillbirth occurs | HG2: Healthy with respect to stunting before corrections | HH2: Disability due to stunting before corrections | HI2: Healthy with respect to stunting | HJ2: Disability due to stunting | HK2: Stunting: Mortality due to other causes sink
A3: soc_rutf_community_19-59_wasting_hm | B3: soc_rutf_community_19-59_wasting_hm | C3: N | D3: N | E3: N | F3: N | G3: N | H3: N | I3: N | J3: N | K3: N | L3: N | M3: N | N3: N | O3: Y | P3: N | R3: N | S3: N | T3: N | U3: N | V3: N | W3: N | X3: N | Y3: N | Z3: N | AA3: N | AB3: N | AC3: N | AD3: N | AE3: N | AF3: N | AG3: N | AH3: N | AI3: N | AJ3: N | AK3: N | AL3: N | AM3: N | AN3: N | AO3: N | AP3: N | AQ3: N | AR3: N | AS3: N | AT3: N | AU3: N | AV3: N | AW3: N | AX3: N | AY3: N | AZ3: N | BA3: N | BB3: N | BC3: N | BD3: N | BE3: N | BF3: N | BG3: N | BH3: N | BI3: N | BJ3: N | BK3: N | BL3: N | BM3: N | BN3: N | BO3: N | BP3: N | BQ3: N | BR3: N | BS3: N | BT3: N | BU3: N | BV3: N | BW3: N | BX3: N | BY3: N | BZ3: N | CA3: N | CB3: N | CC3: N | CD3: N | CE3: N | CF3: N | CG3: N | CH3: N | CI3: N | CJ3: N | CK3: N | CL3: N | CM3: N | CN3: N | CO3: N | CP3: N | CQ3: N | CR3: N | CS3: N | CT3: N | CU3: N | CV3: N | CW3: N | CX3: N | CY3: N | CZ3: N | DA3: N | DB3: N | DC3: N | DD3: N | DE3: N | DF3: N | DG3: N | DH3: N | DI3: N | DJ3: N | DK3: N | DL3: N | DM3: N | DN3: N | DO3: N | DP3: N | DQ3: N | DR3: N | DS3: N | DT3: N | DU3: N | DV3: N | DW3: N | DX3: N | DY3: N | DZ3: N | EA3: N | EB3: N | EC3: N | ED3: N | EE3: N | EF3: N | EG3: N | EH3: N | EI3: N | EJ3: N | EK3: N | EL3: N | EM3: N | EN3: N | EO3: N | EP3: N | EQ3: N | ER3: N | ES3: N | ET3: N | EU3: N | EV3: N | EW3: N | EX3: N | EY3: N | EZ3: N | FA3: N | FB3: N | FC3: N | FD3: N | FE3: N | FF3: N | FG3: N | FH3: N | FI3: N | FJ3: N | FK3: N | FL3: N | FM3: N | FN3: N | FO3: N | FP3: N | FQ3: N | FR3: N | FS3: N | FT3: N | FU3: N | FV3: N | FW3: N | FX3: N | FY3: N | FZ3: N | GA3: N | GB3: N | GC3: N | GD3: N | GE3: N | GF3: N | GG3: N | GH3: N | GI3: N | GJ3: N | GK3: N | GL3: N | GM3: N | GN3: N | GO3: N | GP3: N | GQ3: N | GR3: N | GS3: N | GT3: N | GU3: N | GV3: N | GW3: N | GX3: N | GY3: N | GZ3: N | HA3: Y | HB3: Y | HC3: N | HD3: N | HE3: N | HF3: N | HG3: N | HH3: N | HI3: N | HJ3: N | HK3: N
A4: soc_rutf_community_6-18_wasting_hm | B4: soc_rutf_community_6-18_wasting_hm | C4: N | D4: N | E4: N | F4: N | G4: N | H4: N | I4: N | J4: N | K4: N | L4: N | M4: N | N4: N | O4: Y | P4: N | R4: N | S4: N | T4: N | U4: N | V4: N | W4: N | X4: N | Y4: N | Z4: N | AA4: N | AB4: N | AC4: N | AD4: N | AE4: N | AF4: N | AG4: N | AH4: N | AI4: N | AJ4: N | AK4: N | AL4: N | AM4: N | AN4: N | AO4: N | AP4: N | AQ4: N | AR4: N | AS4: N | AT4: N | AU4: N | AV4: N | AW4: N | AX4: N | AY4: N | AZ4: N | BA4: N | BB4: N | BC4: N | BD4: N | BE4: N | BF4: N | BG4: N | BH4: N | BI4: N | BJ4: N | BK4: N | BL4: N | BM4: N | BN4: N | BO4: N | BP4: N | BQ4: N | BR4: N | BS4: N | BT4: N | BU4: N | BV4: N | BW4: N | BX4: N | BY4: N | BZ4: N | CA4: N | CB4: N | CC4: N | CD4: N | CE4: N | CF4: N | CG4: N | CH4: N | CI4: N | CJ4: N | CK4: N | CL4: N | CM4: N | CN4: N | CO4: N | CP4: N | CQ4: N | CR4: N | CS4: N | CT4: N | CU4: N | CV4: N | CW4: N | CX4: N | CY4: N | CZ4: N | DA4: N | DB4: N | DC4: N | DD4: N | DE4: N | DF4: N | DG4: N | DH4: N | DI4: N | DJ4: N | DK4: N | DL4: N | DM4: N | DN4: N | DO4: N | DP4: N | DQ4: N | DR4: N | DS4: N | DT4: N | DU4: N | DV4: N | DW4: N | DX4: N | DY4: N | DZ4: N | EA4: N | EB4: N | EC4: N | ED4: N | EE4: N | EF4: N | EG4: N | EH4: N | EI4: N | EJ4: N | EK4: N | EL4: N | EM4: N | EN4: N | EO4: N | EP4: N | EQ4: N | ER4: N | ES4: N | ET4: N | EU4: N | EV4: N | EW4: N | EX4: N | EY4: N | EZ4: N | FA4: N | FB4: N | FC4: N | FD4: N | FE4: N | FF4: N | FG4: N | FH4: N | FI4: N | FJ4: N | FK4: N | FL4: N | FM4: N | FN4: N | FO4: N | FP4: N | FQ4: N | FR4: N | FS4: N | FT4: N | FU4: N | FV4: N | FW4: N | FX4: N | FY4: N | FZ4: N | GA4: N | GB4: N | GC4: N | GD4: N | GE4: N | GF4: N | GG4: N | GH4: N | GI4: N | GJ4: N | GK4: N | GL4: N | GM4: N | GN4: N | GO4: N | GP4: N | GQ4: N | GR4: N | GS4: N | GT4: Y | GU4: Y | GV4: N | GW4: N | GX4: N | GY4: N | GZ4: N | HA4: N | HB4: N | HC4: N | HD4: N | HE4: N | HF4: N | HG4: N | HH4: N | HI4: N | HJ4: N | HK4: N
A5: soc_rutf_hospitalized_19-59_wasting_hm | B5: soc_rutf_hospitalized_19-59_wasting_hm | C5: N | D5: N | E5: N | F5: N | G5: N | H5: N | I5: N | J5: N | K5: N | L5: N | M5: N | N5: N | O5: Y | P5: N | R5: N | S5: N | T5: N | U5: N | V5: N | W5: N | X5: N | Y5: N | Z5: N | AA5: N | AB5: N | AC5: N | AD5: N | AE5: N | AF5: N | AG5: N | AH5: N | AI5: N | AJ5: N | AK5: N | AL5: N | AM5: N | AN5: N | AO5: N | AP5: N | AQ5: N | AR5: N | AS5: N | AT5: N | AU5: N | AV5: N | AW5: N | AX5: N | AY5: N | AZ5: N | BA5: N | BB5: N | BC5: N | BD5: N | BE5: N | BF5: N | BG5: N | BH5: N | BI5: N | BJ5: N | BK5: N | BL5: N | BM5: N | BN5: N | BO5: N | BP5: N | BQ5: N | BR5: N | BS5: N | BT5: N | BU5: N | BV5: N | BW5: N | BX5: N | BY5: N | BZ5: N | CA5: N | CB5: N | CC5: N | CD5: N | CE5: N | CF5: N | CG5: N | CH5: N | CI5: N | CJ5: N | CK5: N | CL5: N | CM5: N | CN5: N | CO5: N | CP5: N | CQ5: N | CR5: N | CS5: N | CT5: N | CU5: N | CV5: N | CW5: N | CX5: N | CY5: N | CZ5: N | DA5: N | DB5: N | DC5: N | DD5: N | DE5: N | DF5: N | DG5: N | DH5: N | DI5: N | DJ5: N | DK5: N | DL5: N | DM5: N | DN5: N | DO5: N | DP5: N | DQ5: N | DR5: N | DS5: N | DT5: N | DU5: N | DV5: N | DW5: N | DX5: N | DY5: N | DZ5: N | EA5: N | EB5: N | EC5: N | ED5: N | EE5: N | EF5: N | EG5: N | EH5: N | EI5: N | EJ5: N | EK5: N | EL5: N | EM5: N | EN5: N | EO5: N | EP5: N | EQ5: N | ER5: N | ES5: N | ET5: N | EU5: N | EV5: N | EW5: N | EX5: N | EY5: N | EZ5: N | FA5: N | FB5: N | FC5: N | FD5: N | FE5: N | FF5: N | FG5: N | FH5: N | FI5: N | FJ5: N | FK5: N | FL5: N | FM5: N | FN5: N | FO5: N | FP5: N | FQ5: N | FR5: N | FS5: N | FT5: N | FU5: N | FV5: N | FW5: N | FX5: N | FY5: N | FZ5: N | GA5: N | GB5: N | GC5: N | GD5: N | GE5: N | GF5: N | GG5: N | GH5: N | GI5: N | GJ5: N | GK5: N | GL5: N | GM5: N | GN5: N | GO5: N | GP5: N | GQ5: N | GR5: N | GS5: N | GT5: N | GU5: N | GV5: N | GW5: N | GX5: N | GY5: Y | GZ5: Y | HA5: N | HB5: N | HC5: N | HD5: N | HE5: N | HF5: N | HG5: N | HH5: N | HI5: N | HJ5: N | HK5: N
A6: soc_rutf_hospitalized_6-18_wasting_hm | B6: soc_rutf_hospitalized_6-18_wasting_hm | C6: N | D6: N | E6: N | F6: N | G6: N | H6: N | I6: N | J6: N | K6: N | L6: N | M6: N | N6: N | O6: Y | P6: N | R6: N | S6: N | T6: N | U6: N | V6: N | W6: N | X6: N | Y6: N | Z6: N | AA6: N | AB6: N | AC6: N | AD6: N | AE6: N | AF6: N | AG6: N | AH6: N | AI6: N | AJ6: N | AK6: N | AL6: N | AM6: N | AN6: N | AO6: N | AP6: N | AQ6: N | AR6: N | AS6: N | AT6: N | AU6: N | AV6: N | AW6: N | AX6: N | AY6: N | AZ6: N | BA6: N | BB6: N | BC6: N | BD6: N | BE6: N | BF6: N | BG6: N | BH6: N | BI6: N | BJ6: N | BK6: N | BL6: N | BM6: N | BN6: N | BO6: N | BP6: N | BQ6: N | BR6: N | BS6: N | BT6: N | BU6: N | BV6: N | BW6: N | BX6: N | BY6: N | BZ6: N | CA6: N | CB6: N | CC6: N | CD6: N | CE6: N | CF6: N | CG6: N | CH6: N | CI6: N | CJ6: N | CK6: N | CL6: N | CM6: N | CN6: N | CO6: N | CP6: N | CQ6: N | CR6: N | CS6: N | CT6: N | CU6: N | CV6: N | CW6: N | CX6: N | CY6: N | CZ6: N | DA6: N | DB6: N | DC6: N | DD6: N | DE6: N | DF6: N | DG6: N | DH6: N | DI6: N | DJ6: N | DK6: N | DL6: N | DM6: N | DN6: N | DO6: N | DP6: N | DQ6: N | DR6: N | DS6: N | DT6: N | DU6: N | DV6: N | DW6: N | DX6: N | DY6: N | DZ6: N | EA6: N | EB6: N | EC6: N | ED6: N | EE6: N | EF6: N | EG6: N | EH6: N | EI6: N | EJ6: N | EK6: N | EL6: N | EM6: N | EN6: N | EO6: N | EP6: N | EQ6: N | ER6: N | ES6: N | ET6: N | EU6: N | EV6: N | EW6: N | EX6: N | EY6: N | EZ6: N | FA6: N | FB6: N | FC6: N | FD6: N | FE6: N | FF6: N | FG6: N | FH6: N | FI6: N | FJ6: N | FK6: N | FL6: N | FM6: N | FN6: N | FO6: N | FP6: N | FQ6: N | FR6: N | FS6: N | FT6: N | FU6: N | FV6: N | FW6: N | FX6: N | FY6: N | FZ6: N | GA6: N | GB6: N | GC6: N | GD6: N | GE6: N | GF6: N | GG6: N | GH6: N | GI6: N | GJ6: N | GK6: N | GL6: N | GM6: N | GN6: N | GO6: N | GP6: N | GQ6: N | GR6: Y | GS6: Y | GT6: N | GU6: N | GV6: N | GW6: N | GX6: N | GY6: N | GZ6: N | HA6: N | HB6: N | HC6: N | HD6: N | HE6: N | HF6: N | HG6: N | HH6: N | HI6: N | HJ6: N | HK6: N
A7: soc_iron_tablets_mild_first_trimester_an_hm | B7: soc_iron_tablets_mild_first_trimester_an_hm | C7: N | D7: N | E7: Y | F7: N | G7: N | H7: N | I7: N | J7: N | K7: N | L7: N | M7: N | N7: N | O7: N | P7: N | R7: N | S7: N | T7: N | U7: N | V7: N | W7: N | X7: N | Y7: N | Z7: N | AA7: N | AB7: N | AC7: N | AD7: N | AE7: N | AF7: N | AG7: N | AH7: N | AI7: N | AJ7: N | AK7: N | AL7: N | AM7: N | AN7: N | AO7: Y | AP7: N | AQ7: N | AR7: N | AS7: N | AT7: N | AU7: N | AV7: N | AW7: N | AX7: N | AY7: N | AZ7: N | BA7: N | BB7: N | BC7: N | BD7: N | BE7: N | BF7: N | BG7: N | BH7: N | BI7: N | BJ7: N | BK7: N | BL7: N | BM7: N | BN7: N | BO7: N | BP7: N | BQ7: N | BR7: N | BS7: N | BT7: N | BU7: N | BV7: N | BW7: N | BX7: N | BY7: N | BZ7: N | CA7: N | CB7: N | CC7: N | CD7: N | CE7: N | CF7: N | CG7: N | CH7: N | CI7: N | CJ7: N | CK7: N | CL7: N | CM7: N | CN7: N | CO7: N | CP7: N | CQ7: N | CR7: N | CS7: N | CT7: N | CU7: N | CV7: N | CW7: N | CX7: N | CY7: N | CZ7: N | DA7: N | DB7: N | DC7: N | DD7: N | DE7: N | DF7: N | DG7: N | DH7: N | DI7: N | DJ7: N | DK7: N | DL7: N | DM7: N | DN7: N | DO7: N | DP7: N | DQ7: N | DR7: N | DS7: N | DT7: N | DU7: N | DV7: N | DW7: N | DX7: N | DY7: N | DZ7: N | EA7: N | EB7: N | EC7: N | ED7: N | EE7: N | EF7: N | EG7: N | EH7: N | EI7: N | EJ7: N | EK7: N | EL7: N | EM7: N | EN7: N | EO7: N | EP7: N | EQ7: N | ER7: N | ES7: N | ET7: N | EU7: N | EV7: N | EW7: N | EX7: N | EY7: N | EZ7: N | FA7: N | FB7: N | FC7: N | FD7: N | FE7: N | FF7: N | FG7: N | FH7: N | FI7: N | FJ7: N | FK7: N | FL7: N | FM7: N | FN7: N | FO7: N | FP7: N | FQ7: N | FR7: N | FS7: N | FT7: N | FU7: N | FV7: N | FW7: N | FX7: N | FY7: N | FZ7: N | GA7: N | GB7: N | GC7: N | GD7: N | GE7: N | GF7: N | GG7: N | GH7: N | GI7: N | GJ7: N | GK7: N | GL7: N | GM7: N | GN7: N | GO7: N | GP7: N | GQ7: N | GR7: N | GS7: N | GT7: N | GU7: N | GV7: N | GW7: N | GX7: N | GY7: N | GZ7: N | HA7: N | HB7: N | HC7: N | HD7: N | HE7: N | HF7: N | HG7: N | HH7: N | HI7: N | HJ7: N | HK7: N
A8: soc_iron_tablets_mild_second_trimester_an_hm | B8: soc_iron_tablets_mild_second_trimester_an_hm | C8: N | D8: N | E8: Y | F8: N | G8: N | H8: N | I8: N | J8: N | K8: N | L8: N | M8: N | N8: N | O8: N | P8: N | R8: N | S8: N | T8: N | U8: N | V8: N | W8: N | X8: N | Y8: N | Z8: N | AA8: N | AB8: N | AC8: N | AD8: N | AE8: N | AF8: N | AG8: N | AH8: N | AI8: N | AJ8: N | AK8: N | AL8: N | AM8: N | AN8: N | AO8: N | AP8: N | AQ8: N | AR8: N | AS8: N | AT8: N | AU8: N | AV8: N | AW8: N | AX8: N | AY8: N | AZ8: Y | BA8: N | BB8: N | BC8: N | BD8: N | BE8: N | BF8: N | BG8: N | BH8: N | BI8: N | BJ8: N | BK8: N | BL8: N | BM8: N | BN8: N | BO8: N | BP8: N | BQ8: N | BR8: N | BS8: N | BT8: N | BU8: N | BV8: N | BW8: N | BX8: N | BY8: N | BZ8: N | CA8: N | CB8: N | CC8: N | CD8: N | CE8: N | CF8: N | CG8: N | CH8: N | CI8: N | CJ8: N | CK8: N | CL8: N | CM8: N | CN8: N | CO8: N | CP8: N | CQ8: N | CR8: N | CS8: N | CT8: N | CU8: N | CV8: N | CW8: N | CX8: N | CY8: N | CZ8: N | DA8: N | DB8: N | DC8: N | DD8: N | DE8: N | DF8: N | DG8: N | DH8: N | DI8: N | DJ8: N | DK8: N | DL8: N | DM8: N | DN8: N | DO8: N | DP8: N | DQ8: N | DR8: N | DS8: N | DT8: N | DU8: N | DV8: N | DW8: N | DX8: N | DY8: N | DZ8: N | EA8: N | EB8: N | EC8: N | ED8: N | EE8: N | EF8: N | EG8: N | EH8: N | EI8: N | EJ8: N | EK8: N | EL8: N | EM8: N | EN8: N | EO8: N | EP8: N | EQ8: N | ER8: N | ES8: N | ET8: N | EU8: N | EV8: N | EW8: N | EX8: N | EY8: N | EZ8: N | FA8: N | FB8: N | FC8: N | FD8: N | FE8: N | FF8: N | FG8: N | FH8: N | FI8: N | FJ8: N | FK8: N | FL8: N | FM8: N | FN8: N | FO8: N | FP8: N | FQ8: N | FR8: N | FS8: N | FT8: N | FU8: N | FV8: N | FW8: N | FX8: N | FY8: N | FZ8: N | GA8: N | GB8: N | GC8: N | GD8: N | GE8: N | GF8: N | GG8: N | GH8: N | GI8: N | GJ8: N | GK8: N | GL8: N | GM8: N | GN8: N | GO8: N | GP8: N | GQ8: N | GR8: N | GS8: N | GT8: N | GU8: N | GV8: N | GW8: N | GX8: N | GY8: N | GZ8: N | HA8: N | HB8: N | HC8: N | HD8: N | HE8: N | HF8: N | HG8: N | HH8: N | HI8: N | HJ8: N | HK8: N
A9: soc_iron_tablets_moderate_first_trimester_an_hm | B9: soc_iron_tablets_moderate_first_trimester_an_hm | C9: N | D9: N | E9: Y | F9: N | G9: N | H9: N | I9: N | J9: N | K9: N | L9: N | M9: N | N9: N | O9: N | P9: N | R9: N | S9: N | T9: N | U9: N | V9: N | W9: N | X9: N | Y9: N | Z9: N | AA9: N | AB9: N | AC9: N | AD9: N | AE9: N | AF9: N | AG9: N | AH9: N | AI9: N | AJ9: N | AK9: N | AL9: N | AM9: N | AN9: N | AO9: N | AP9: Y | AQ9: N | AR9: N | AS9: N | AT9: N | AU9: N | AV9: N | AW9: N | AX9: N | AY9: N | AZ9: N | BA9: N | BB9: N | BC9: N | BD9: N | BE9: N | BF9: N | BG9: N | BH9: N | BI9: N | BJ9: N | BK9: N | BL9: N | BM9: N | BN9: N | BO9: N | BP9: N | BQ9: N | BR9: N | BS9: N | BT9: N | BU9: N | BV9: N | BW9: N | BX9: N | BY9: N | BZ9: N | CA9: N | CB9: N | CC9: N | CD9: N | CE9: N | CF9: N | CG9: N | CH9: N | CI9: N | CJ9: N | CK9: N | CL9: N | CM9: N | CN9: N | CO9: N | CP9: N | CQ9: N | CR9: N | CS9: N | CT9: N | CU9: N | CV9: N | CW9: N | CX9: N | CY9: N | CZ9: N | DA9: N | DB9: N | DC9: N | DD9: N | DE9: N | DF9: N | DG9: N | DH9: N | DI9: N | DJ9: N | DK9: N | DL9: N | DM9: N | DN9: N | DO9: N | DP9: N | DQ9: N | DR9: N | DS9: N | DT9: N | DU9: N | DV9: N | DW9: N | DX9: N | DY9: N | DZ9: N | EA9: N | EB9: N | EC9: N | ED9: N | EE9: N | EF9: N | EG9: N | EH9: N | EI9: N | EJ9: N | EK9: N | EL9: N | EM9: N | EN9: N | EO9: N | EP9: N | EQ9: N | ER9: N | ES9: N | ET9: N | EU9: N | EV9: N | EW9: N | EX9: N | EY9: N | EZ9: N | FA9: N | FB9: N | FC9: N | FD9: N | FE9: N | FF9: N | FG9: N | FH9: N | FI9: N | FJ9: N | FK9: N | FL9: N | FM9: N | FN9: N | FO9: N | FP9: N | FQ9: N | FR9: N | FS9: N | FT9: N | FU9: N | FV9: N | FW9: N | FX9: N | FY9: N | FZ9: N | GA9: N | GB9: N | GC9: N | GD9: N | GE9: N | GF9: N | GG9: N | GH9: N | GI9: N | GJ9: N | GK9: N | GL9: N | GM9: N | GN9: N | GO9: N | GP9: N | GQ9: N | GR9: N | GS9: N | GT9: N | GU9: N | GV9: N | GW9: N | GX9: N | GY9: N | GZ9: N | HA9: N | HB9: N | HC9: N | HD9: N | HE9: N | HF9: N | HG9: N | HH9: N | HI9: N | HJ9: N | HK9: N
A10: soc_iron_tablets_moderate_second_trimester_an_hm | B10: soc_iron_tablets_moderate_second_trimester_an_hm | C10: N | D10: N | E10: Y | F10: N | G10: N | H10: N | I10: N | J10: N | K10: N | L10: N | M10: N | N10: N | O10: N | P10: N | R10: N | S10: N | T10: N | U10: N | V10: N | W10: N | X10: N | Y10: N | Z10: N | AA10: N | AB10: N | AC10: N | AD10: N | AE10: N | AF10: N | AG10: N | AH10: N | AI10: N | AJ10: N | AK10: N | AL10: N | AM10: N | AN10: N | AO10: N | AP10: N | AQ10: N | AR10: N | AS10: N | AT10: N | AU10: N | AV10: N | AW10: N | AX10: N | AY10: N | AZ10: N | BA10: Y | BB10: N | BC10: N | BD10: N | BE10: N | BF10: N | BG10: N | BH10: N | BI10: N | BJ10: N | BK10: N | BL10: N | BM10: N | BN10: N | BO10: N | BP10: N | BQ10: N | BR10: N | BS10: N | BT10: N | BU10: N | BV10: N | BW10: N | BX10: N | BY10: N | BZ10: N | CA10: N | CB10: N | CC10: N | CD10: N | CE10: N | CF10: N | CG10: N | CH10: N | CI10: N | CJ10: N | CK10: N | CL10: N | CM10: N | CN10: N | CO10: N | CP10: N | CQ10: N | CR10: N | CS10: N | CT10: N | CU10: N | CV10: N | CW10: N | CX10: N | CY10: N | CZ10: N | DA10: N | DB10: N | DC10: N | DD10: N | DE10: N | DF10: N | DG10: N | DH10: N | DI10: N | DJ10: N | DK10: N | DL10: N | DM10: N | DN10: N | DO10: N | DP10: N | DQ10: N | DR10: N | DS10: N | DT10: N | DU10: N | DV10: N | DW10: N | DX10: N | DY10: N | DZ10: N | EA10: N | EB10: N | EC10: N | ED10: N | EE10: N | EF10: N | EG10: N | EH10: N | EI10: N | EJ10: N | EK10: N | EL10: N | EM10: N | EN10: N | EO10: N | EP10: N | EQ10: N | ER10: N | ES10: N | ET10: N | EU10: N | EV10: N | EW10: N | EX10: N | EY10: N | EZ10: N | FA10: N | FB10: N | FC10: N | FD10: N | FE10: N | FF10: N | FG10: N | FH10: N | FI10: N | FJ10: N | FK10: N | FL10: N | FM10: N | FN10: N | FO10: N | FP10: N | FQ10: N | FR10: N | FS10: N | FT10: N | FU10: N | FV10: N | FW10: N | FX10: N | FY10: N | FZ10: N | GA10: N | GB10: N | GC10: N | GD10: N | GE10: N | GF10: N | GG10: N | GH10: N | GI10: N | GJ10: N | GK10: N | GL10: N | GM10: N | GN10: N | GO10: N | GP10: N | GQ10: N | GR10: N | GS10: N | GT10: N | GU10: N | GV10: N | GW10: N | GX10: N | GY10: N | GZ10: N | HA10: N | HB10: N | HC10: N | HD10: N | HE10: N | HF10: N | HG10: N | HH10: N | HI10: N | HJ10: N | HK10: N
A11: soc_iron_tablets_severe_first_trimester_an_hm | B11: soc_iron_tablets_severe_first_trimester_an_hm | C11: N | D11: N | E11: Y | F11: N | G11: N | H11: N | I11: N | J11: N | K11: N | L11: N | M11: N | N11: N | O11: N | P11: N | R11: N | S11: N | T11: N | U11: N | V11: N | W11: N | X11: N | Y11: N | Z11: N | AA11: N | AB11: N | AC11: N | AD11: N | AE11: N | AF11: N | AG11: N | AH11: N | AI11: N | AJ11: N | AK11: N | AL11: N | AM11: N | AN11: N | AO11: N | AP11: N | AQ11: Y | AR11: N | AS11: N | AT11: N | AU11: N | AV11: N | AW11: N | AX11: N | AY11: N | AZ11: N | BA11: N | BB11: N | BC11: N | BD11: N | BE11: N | BF11: N | BG11: N | BH11: N | BI11: N | BJ11: N | BK11: N | BL11: N | BM11: N | BN11: N | BO11: N | BP11: N | BQ11: N | BR11: N | BS11: N | BT11: N | BU11: N | BV11: N | BW11: N | BX11: N | BY11: N | BZ11: N | CA11: N | CB11: N | CC11: N | CD11: N | CE11: N | CF11: N | CG11: N | CH11: N | CI11: N | CJ11: N | CK11: N | CL11: N | CM11: N | CN11: N | CO11: N | CP11: N | CQ11: N | CR11: N | CS11: N | CT11: N | CU11: N | CV11: N | CW11: N | CX11: N | CY11: N | CZ11: N | DA11: N | DB11: N | DC11: N | DD11: N | DE11: N | DF11: N | DG11: N | DH11: N | DI11: N | DJ11: N | DK11: N | DL11: N | DM11: N | DN11: N | DO11: N | DP11: N | DQ11: N | DR11: N | DS11: N | DT11: N | DU11: N | DV11: N | DW11: N | DX11: N | DY11: N | DZ11: N | EA11: N | EB11: N | EC11: N | ED11: N | EE11: N | EF11: N | EG11: N | EH11: N | EI11: N | EJ11: N | EK11: N | EL11: N | EM11: N | EN11: N | EO11: N | EP11: N | EQ11: N | ER11: N | ES11: N | ET11: N | EU11: N | EV11: N | EW11: N | EX11: N | EY11: N | EZ11: N | FA11: N | FB11: N | FC11: N | FD11: N | FE11: N | FF11: N | FG11: N | FH11: N | FI11: N | FJ11: N | FK11: N | FL11: N | FM11: N | FN11: N | FO11: N | FP11: N | FQ11: N | FR11: N | FS11: N | FT11: N | FU11: N | FV11: N | FW11: N | FX11: N | FY11: N | FZ11: N | GA11: N | GB11: N | GC11: N | GD11: N | GE11: N | GF11: N | GG11: N | GH11: N | GI11: N | GJ11: N | GK11: N | GL11: N | GM11: N | GN11: N | GO11: N | GP11: N | GQ11: N | GR11: N | GS11: N | GT11: N | GU11: N | GV11: N | GW11: N | GX11: N | GY11: N | GZ11: N | HA11: N | HB11: N | HC11: N | HD11: N | HE11: N | HF11: N | HG11: N | HH11: N | HI11: N | HJ11: N | HK11: N
A12: soc_iron_tablets_severe_second_trimester_an_hm | B12: soc_iron_tablets_severe_second_trimester_an_hm | C12: N | D12: N | E12: Y | F12: N | G12: N | H12: N | I12: N | J12: N | K12: N | L12: N | M12: N | N12: N | O12: N | P12: N | R12: N | S12: N | T12: N | U12: N | V12: N | W12: N | X12: N | Y12: N | Z12: N | AA12: N | AB12: N | AC12: N | AD12: N | AE12: N | AF12: N | AG12: N | AH12: N | AI12: N | AJ12: N | AK12: N | AL12: N | AM12: N | AN12: N | AO12: N | AP12: N | AQ12: N | AR12: N | AS12: N | AT12: N | AU12: N | AV12: N | AW12: N | AX12: N | AY12: N | AZ12: N | BA12: N | BB12: Y | BC12: N | BD12: N | BE12: N | BF12: N | BG12: N | BH12: N | BI12: N | BJ12: N | BK12: N | BL12: N | BM12: N | BN12: N | BO12: N | BP12: N | BQ12: N | BR12: N | BS12: N | BT12: N | BU12: N | BV12: N | BW12: N | BX12: N | BY12: N | BZ12: N | CA12: N | CB12: N | CC12: N | CD12: N | CE12: N | CF12: N | CG12: N | CH12: N | CI12: N | CJ12: N | CK12: N | CL12: N | CM12: N | CN12: N | CO12: N | CP12: N | CQ12: N | CR12: N | CS12: N | CT12: N | CU12: N | CV12: N | CW12: N | CX12: N | CY12: N | CZ12: N | DA12: N | DB12: N | DC12: N | DD12: N | DE12: N | DF12: N | DG12: N | DH12: N | DI12: N | DJ12: N | DK12: N | DL12: N | DM12: N | DN12: N | DO12: N | DP12: N | DQ12: N | DR12: N | DS12: N | DT12: N | DU12: N | DV12: N | DW12: N | DX12: N | DY12: N | DZ12: N | EA12: N | EB12: N | EC12: N | ED12: N | EE12: N | EF12: N | EG12: N | EH12: N | EI12: N | EJ12: N | EK12: N | EL12: N | EM12: N | EN12: N | EO12: N | EP12: N | EQ12: N | ER12: N | ES12: N | ET12: N | EU12: N | EV12: N | EW12: N | EX12: N | EY12: N | EZ12: N | FA12: N | FB12: N | FC12: N | FD12: N | FE12: N | FF12: N | FG12: N | FH12: N | FI12: N | FJ12: N | FK12: N | FL12: N | FM12: N | FN12: N | FO12: N | FP12: N | FQ12: N | FR12: N | FS12: N | FT12: N | FU12: N | FV12: N | FW12: N | FX12: N | FY12: N | FZ12: N | GA12: N | GB12: N | GC12: N | GD12: N | GE12: N | GF12: N | GG12: N | GH12: N | GI12: N | GJ12: N | GK12: N | GL12: N | GM12: N | GN12: N | GO12: N | GP12: N | GQ12: N | GR12: N | GS12: N | GT12: N | GU12: N | GV12: N | GW12: N | GX12: N | GY12: N | GZ12: N | HA12: N | HB12: N | HC12: N | HD12: N | HE12: N | HF12: N | HG12: N | HH12: N | HI12: N | HJ12: N | HK12: N
A13: noninvasive_hb_diagnostic_first_trimester_an_hm | B13: noninvasive_hb_diagnostic_first_trimester_an_hm | C13: N | D13: N | E13: Y | F13: N | G13: N | H13: N | I13: N | J13: N | K13: N | L13: N | M13: N | N13: N | O13: N | P13: N | R13: N | S13: N | T13: N | U13: N | V13: N | W13: N | X13: N | Y13: N | Z13: N | AA13: N | AB13: N | AC13: N | AD13: N | AE13: N | AF13: N | AG13: N | AH13: N | AI13: N | AJ13: N | AK13: N | AL13: N | AM13: N | AN13: Y | AO13: N | AP13: N | AQ13: N | AR13: N | AS13: N | AT13: N | AU13: N | AV13: N | AW13: N | AX13: N | AY13: N | AZ13: N | BA13: N | BB13: N | BC13: N | BD13: N | BE13: N | BF13: N | BG13: N | BH13: N | BI13: N | BJ13: N | BK13: N | BL13: N | BM13: N | BN13: N | BO13: N | BP13: N | BQ13: N | BR13: N | BS13: N | BT13: N | BU13: N | BV13: N | BW13: N | BX13: N | BY13: N | BZ13: N | CA13: N | CB13: N | CC13: N | CD13: N | CE13: N | CF13: N | CG13: N | CH13: N | CI13: N | CJ13: N | CK13: N | CL13: N | CM13: N | CN13: N | CO13: N | CP13: N | CQ13: N | CR13: N | CS13: N | CT13: N | CU13: N | CV13: N | CW13: N | CX13: N | CY13: N | CZ13: N | DA13: N | DB13: N | DC13: N | DD13: N | DE13: N | DF13: N | DG13: N | DH13: N | DI13: N | DJ13: N | DK13: N | DL13: N | DM13: N | DN13: N | DO13: N | DP13: N | DQ13: N | DR13: N | DS13: N | DT13: N | DU13: N | DV13: N | DW13: N | DX13: N | DY13: N | DZ13: N | EA13: N | EB13: N | EC13: N | ED13: N | EE13: N | EF13: N | EG13: N | EH13: N | EI13: N | EJ13: N | EK13: N | EL13: N | EM13: N | EN13: N | EO13: N | EP13: N | EQ13: N | ER13: N | ES13: N | ET13: N | EU13: N | EV13: N | EW13: N | EX13: N | EY13: N | EZ13: N | FA13: N | FB13: N | FC13: N | FD13: N | FE13: N | FF13: N | FG13: N | FH13: N | FI13: N | FJ13: N | FK13: N | FL13: N | FM13: N | FN13: N | FO13: N | FP13: N | FQ13: N | FR13: N | FS13: N | FT13: N | FU13: N | FV13: N | FW13: N | FX13: N | FY13: N | FZ13: N | GA13: N | GB13: N | GC13: N | GD13: N | GE13: N | GF13: N | GG13: N | GH13: N | GI13: N | GJ13: N | GK13: N | GL13: N | GM13: N | GN13: N | GO13: N | GP13: N | GQ13: N | GR13: N | GS13: N | GT13: N | GU13: N | GV13: N | GW13: N | GX13: N | GY13: N | GZ13: N | HA13: N | HB13: N | HC13: N | HD13: N | HE13: N | HF13: N | HG13: N | HH13: N | HI13: N | HJ13: N | HK13: N
... A20: soc_preeclampsia_treatment_third_trimester_severe_preecl_hm | B20: soc_preeclampsia_treatment_third_trimester_severe_preecl_hm | C20: N | D20: N | E20: N | F20: N | G20: N | H20: Y | I20: N | J20: N | K20: N | L20: N | M20: N | N20: N | O20: N | P20: N | R20: N | S20: N | T20: N | U20: N | V20: N | W20: N | X20: N | Y20: N | Z20: N | AA20: N | AB20: N | AC20: N | AD20: N | AE20: N | AF20: N | AG20: N | AH20: N | AI20: N | AJ20: N | AK20: N | AL20: N | AM20: N | AN20: N | AO20: N | AP20: N | AQ20: N | AR20: N | AS20: N | AT20: N | AU20: N | AV20: N | AW20: N | AX20: N | AY20: N | AZ20: N | BA20: N | BB20: N | BC20: N | BD20: N | BE20: N | BF20: N | BG20: N | BH20: N | BI20: N | BJ20: N | BK20: N | BL20: N | BM20: N | BN20: N | BO20: N | BP20: N | BQ20: N | BR20: N | BS20: N | BT20: N | BU20: N | BV20: N | BW20: N | BX20: N | BY20: N | BZ20: N | CA20: N | CB20: N | CC20: N | CD20: N | CE20: N | CF20: N | CG20: N | CH20: N | CI20: N | CJ20: N | CK20: N | CL20: N | CM20: N | CN20: N | CO20: N | CP20: N | CQ20: N | CR20: N | CS20: N | CT20: N | CU20: N | CV20: N | CW20: N | CX20: N | CY20: N | CZ20: N | DA20: N | DB20: N | DC20: N | DD20: N | DE20: N | DF20: Y | DG20: N | DH20: N | DI20: N | DJ20: N | DK20: N | DL20: N | DM20: N | DN20: N | DO20: N | DP20: N | DQ20: N | DR20: N | DS20: N | DT20: N | DU20: N | DV20: N | DW20: N | DX20: N | DY20: N | DZ20: N | EA20: N | EB20: N | EC20: N | ED20: N | EE20: N | EF20: N | EG20: N | EH20: N | EI20: N | EJ20: N | EK20: N | EL20: N | EM20: N | EN20: N | EO20: N | EP20: N | EQ20: N | ER20: N | ES20: N | ET20: N | EU20: N | EV20: N | EW20: N | EX20: N | EY20: N | EZ20: N | FA20: N | FB20: N | FC20: N | FD20: N | FE20: N | FF20: N | FG20: N | FH20: N | FI20: N | FJ20: N | FK20: N | FL20: N | FM20: N | FN20: N | FO20: N | FP20: N | FQ20: N | FR20: N | FS20: N | FT20: N | FU20: N | FV20: N | FW20: N | FX20: N | FY20: N | FZ20: N | GA20: N | GB20: N | GC20: N | GD20: N | GE20: N | GF20: N | GG20: N | GH20: N | GI20: N | GJ20: N | GK20: N | GL20: N | GM20: N | GN20: N | GO20: N | GP20: N | GQ20: N | GR20: N | GS20: N | GT20: N | GU20: N | GV20: N | GW20: N | GX20: N | GY20: N | GZ20: N | HA20: N | HB20: N | HC20: N | HD20: N | HE20: N | HF20: N | HG20: N | HH20: N | HI20: N | HJ20: N | HK20: N

Sheet Spending data
A1: ='Program targeting'!$B$3 -> soc_rutf_community_19-59_wasting_hm | B1: Provenance | C1: Units | D1: Uncertainty | E1: Assumption | G1: 2015 | H1: 2015.25 | I1: 2015.5 | J1: 2015.75 | K1: 2016 | L1: 2016.25 | M1: 2016.5 | N1: 2016.75 | O1: 2017 | P1: 2017.25 | Q1: 2017.5 | R1: 2017.75 | S1: 2018 | T1: 2018.25 | U1: 2018.5 | V1: 2018.75 | W1: 2019 | X1: 2019.25 | Y1: 2019.5 | Z1: 2019.75 | AA1: 2020 | AB1: 2020.25 | AC1: 2020.5 | AD1: 2020.75 | AE1: 2021 | AF1: 2021.25 | AG1: 2021.5 | AH1: 2021.75 | AI1: 2022 | AJ1: 2022.25 | AK1: 2022.5 | AL1: 2022.75 | AM1: 2023 | AN1: 2023.25 | AO1: 2023.5 | AP1: 2023.75 | AQ1: 2024 | AR1: 2024.25 | AS1: 2024.5 | AT1: 2024.75 | AU1: 2025 | AV1: 2025.25 | AW1: 2025.5 | AX1: 2025.75 | AY1: 2026 | AZ1: 2026.25 | BA1: 2026.5 | BB1: 2026.75 | BC1: 2027 | BD1: 2027.25 | BE1: 2027.5 | BF1: 2027.75 | BG1: 2028 | BH1: 2028.25 | BI1: 2028.5 | BJ1: 2028.75 | BK1: 2029 | BL1: 2029.25 | BM1: 2029.5 | BN1: 2029.75 | BO1: 2030 | BP1: 2030.25 | BQ1: 2030.5 | BR1: 2030.75 | BS1: 2031 | BT1: 2031.25 | BU1: 2031.5 | BV1: 2031.75 | BW1: 2032 | BX1: 2032.25 | BY1: 2032.5 | BZ1: 2032.75 | CA1: 2033 | CB1: 2033.25 | CC1: 2033.5 | CD1: 2033.75 | CE1: 2034 | CF1: 2034.25 | CG1: 2034.5 | CH1: 2034.75 | CI1: 2035 | CJ1: 2035.25 | CK1: 2035.5 | CL1: 2035.75 | CM1: 2036 | CN1: 2036.25 | CO1: 2036.5 | CP1: 2036.75 | CQ1: 2037 | CR1: 2037.25 | CS1: 2037.5 | CT1: 2037.75 | CU1: 2038 | CV1: 2038.25 | CW1: 2038.5 | CX1: 2038.75 | CY1: 2039 | CZ1: 2039.25 | DA1: 2039.5 | DB1: 2039.75 | DC1: 2040 | DD1: 2040.25 | DE1: 2040.5 | DF1: 2040.75 | DG1: 2041 | DH1: 2041.25 | DI1: 2041.5 | DJ1: 2041.75 | DK1: 2042 | DL1: 2042.25 | DM1: 2042.5 | DN1: 2042.75 | DO1: 2043 | DP1: 2043.25 | DQ1: 2043.5 | DR1: 2043.75 | DS1: 2044 | DT1: 2044.25 | DU1: 2044.5 | DV1: 2044.75 | DW1: 2045 | DX1: 2045.25 | DY1: 2045.5 | DZ1: 2045.75 | EA1: 2046 | EB1: 2046.25 | EC1: 2046.5 | ED1: 2046.75 | EE1: 2047 | EF1: 2047.25 | EG1: 2047.5 | EH1: 2047.75 | EI1: 2048 | EJ1: 2048.25 | EK1: 2048.5 | EL1: 2048.75 | EM1: 2049 | EN1: 2049.25 | EO1: 2049.5 | EP1: 2049.75 | EQ1: 2050 | ER1: 2050.25 | ES1: 2050.5 | ET1: 2050.75 | EU1: 2051 | EV1: 2051.25 | EW1: 2051.5 | EX1: 2051.75
A2: Annual spend | C2: $/year | F2: OR | G2: 1e+15 | H2: 1e+15 | I2: 1e+15 | J2: 1e+15 | K2: 1e+15 | L2: 1e+15 | M2: 1e+15 | N2: 1e+15 | O2: 1e+15 | P2: 1e+15 | Q2: 1e+15 | R2: 1e+15 | S2: 1e+15 | T2: 1e+15 | U2: 1e+15 | V2: 1e+15 | W2: 1e+15 | X2: 1e+15 | Y2: 1e+15 | Z2: 1e+15 | AA2: 1e+15 | AB2: 1e+15 | AC2: 1e+15 | AD2: 1e+15 | AE2: 1e+15 | AF2: 1e+15 | AG2: 1e+15 | AH2: 1e+15 | AI2: 1e+15 | AJ2: 1e+15 | AK2: 1e+15 | AL2: 1e+15 | AM2: 1e+15 | AN2: 1e+15 | AO2: 1e+15 | AP2: 1e+15 | AQ2: 1e+15 | AR2: 1e+15 | AS2: 1e+15 | AT2: 1e+15 | AU2: 1e+15 | AV2: 1e+15 | AW2: 1e+15 | AX2: 1e+15 | AY2: 1e+15 | AZ2: 1e+15 | BA2: 1e+15 | BB2: 1e+15 | BC2: 1e+15 | BD2: 1e+15 | BE2: 1e+15 | BF2: 1e+15 | BG2: 1e+15 | BH2: 1e+15 | BI2: 1e+15 | BJ2: 1e+15 | BK2: 1e+15 | BL2: 1e+15 | BM2: 1e+15 | BN2: 1e+15 | BO2: 1e+15 | BP2: 1e+15 | BQ2: 1e+15 | BR2: 1e+15 | BS2: 1e+15 | BT2: 1e+15 | BU2: 1e+15 | BV2: 1e+15 | BW2: 1e+15 | BX2: 1e+15 | BY2: 1e+15 | BZ2: 1e+15 | CA2: 1e+15 | CB2: 1e+15 | CC2: 1e+15 | CD2: 1e+15 | CE2: 1e+15 | CF2: 1e+15 | CG2: 1e+15 | CH2: 1e+15 | CI2: 1e+15 | CJ2: 1e+15 | CK2: 1e+15 | CL2: 1e+15 | CM2: 1e+15 | CN2: 1e+15 | CO2: 1e+15 | CP2: 1e+15 | CQ2: 1e+15 | CR2: 1e+15 | CS2: 1e+15 | CT2: 1e+15 | CU2: 1e+15 | CV2: 1e+15 | CW2: 1e+15 | CX2: 1e+15 | CY2: 1e+15 | CZ2: 1e+15 | DA2: 1e+15 | DB2: 1e+15 | DC2: 1e+15 | DD2: 1e+15 | DE2: 1e+15 | DF2: 1e+15 | DG2: 1e+15 | DH2: 1e+15 | DI2: 1e+15 | DJ2: 1e+15 | DK2: 1e+15 | DL2: 1e+15 | DM2: 1e+15 | DN2: 1e+15 | DO2: 1e+15 | DP2: 1e+15 | DQ2: 1e+15 | DR2: 1e+15 | DS2: 1e+15 | DT2: 1e+15 | DU2: 1e+15 | DV2: 1e+15 | DW2: 1e+15 | DX2: 1e+15 | DY2: 1e+15 | DZ2: 1e+15 | EA2: 1e+15 | EB2: 1e+15 | EC2: 1e+15 | ED2: 1e+15 | EE2: 1e+15 | EF2: 1e+15 | EG2: 1e+15 | EH2: 1e+15 | EI2: 1e+15 | EJ2: 1e+15 | EK2: 1e+15 | EL2: 1e+15 | EM2: 1e+15 | EN2: 1e+15 | EO2: 1e+15 | EP2: 1e+15 | EQ2: 1e+15 | ER2: 1e+15 | ES2: 1e+15 | ET2: 1e+15 | EU2: 1e+15 | EV2: 1e+15 | EW2: 1e+15 | EX2: 1e+15
A3: Unit cost | C3: $/person | F3: OR | G3: 23.847312 | H3: 23.847312 | I3: 23.847312 | J3: 23.847312 | K3: 23.847312 | L3: 23.847312 | M3: 23.847312 | N3: 23.847312 | O3: 23.847312 | P3: 23.847312 | Q3: 23.847312 | R3: 23.847312 | S3: 23.847312 | T3: 23.847312 | U3: 23.847312 | V3: 23.847312 | W3: 23.847312 | X3: 23.847312 | Y3: 23.847312 | Z3: 23.847312 | AA3: 23.847312 | AB3: 23.847312 | AC3: 23.847312 | AD3: 23.847312 | AE3: 23.847312 | AF3: 23.847312 | AG3: 23.847312 | AH3: 23.847312 | AI3: 23.847312 | AJ3: 23.847312 | AK3: 23.847312 | AL3: 23.847312 | AM3: 23.847312 | AN3: 23.847312 | AO3: 23.847312 | AP3: 23.847312 | AQ3: 23.847312 | AR3: 23.847312 | AS3: 23.847312 | AT3: 23.847312 | AU3: 23.847312 | AV3: 23.847312 | AW3: 23.847312 | AX3: 23.847312 | AY3: 23.847312 | AZ3: 23.847312 | BA3: 23.847312 | BB3: 23.847312 | BC3: 23.847312 | BD3: 23.847312 | BE3: 23.847312 | BF3: 23.847312 | BG3: 23.847312 | BH3: 23.847312 | BI3: 23.847312 | BJ3: 23.847312 | BK3: 23.847312 | BL3: 23.847312 | BM3: 23.847312 | BN3: 23.847312 | BO3: 23.847312 | BP3: 23.847312 | BQ3: 23.847312 | BR3: 23.847312 | BS3: 23.847312 | BT3: 23.847312 | BU3: 23.847312 | BV3: 23.847312 | BW3: 23.847312 | BX3: 23.847312 | BY3: 23.847312 | BZ3: 23.847312 | CA3: 23.847312 | CB3: 23.847312 | CC3: 23.847312 | CD3: 23.847312 | CE3: 23.847312 | CF3: 23.847312 | CG3: 23.847312 | CH3: 23.847312 | CI3: 23.847312 | CJ3: 23.847312 | CK3: 23.847312 | CL3: 23.847312 | CM3: 23.847312 | CN3: 23.847312 | CO3: 23.847312 | CP3: 23.847312 | CQ3: 23.847312 | CR3: 23.847312 | CS3: 23.847312 | CT3: 23.847312 | CU3: 23.847312 | CV3: 23.847312 | CW3: 23.847312 | CX3: 23.847312 | CY3: 23.847312 | CZ3: 23.847312 | DA3: 23.847312 | DB3: 23.847312 | DC3: 23.847312 | DD3: 23.847312 | DE3: 23.847312 | DF3: 23.847312 | DG3: 23.847312 | DH3: 23.847312 | DI3: 23.847312 | DJ3: 23.847312 | DK3: 23.847312 | DL3: 23.847312 | DM3: 23.847312 | DN3: 23.847312 | DO3: 23.847312 | DP3: 23.847312 | DQ3: 23.847312 | DR3: 23.847312 | DS3: 23.847312 | DT3: 23.847312 | DU3: 23.847312 | DV3: 23.847312 | DW3: 23.847312 | DX3: 23.847312 | DY3: 23.847312 | DZ3: 23.847312 | EA3: 23.847312 | EB3: 23.847312 | EC3: 23.847312 | ED3: 23.847312 | EE3: 23.847312 | EF3: 23.847312 | EG3: 23.847312 | EH3: 23.847312 | EI3: 23.847312 | EJ3: 23.847312 | EK3: 23.847312 | EL3: 23.847312 | EM3: 23.847312 | EN3: 23.847312 | EO3: 23.847312 | EP3: 23.847312 | EQ3: 23.847312 | ER3: 23.847312 | ES3: 23.847312 | ET3: 23.847312 | EU3: 23.847312 | EV3: 23.847312 | EW3: 23.847312 | EX3: 23.847312
A4: Capacity constraint | C4: people/year | F4: OR
A5: Saturation | C5: N.A. | F5: OR
A6: Coverage | C6: people/year | E6: 100000 | F6: OR
A8: ='Program targeting'!$B$4 -> soc_rutf_community_6-18_wasting_hm | B8: Provenance | C8: Units | D8: Uncertainty | E8: Assumption | G8: 2015 | H8: 2015.25 | I8: 2015.5 | J8: 2015.75 | K8: 2016 | L8: 2016.25 | M8: 2016.5 | N8: 2016.75 | O8: 2017 | P8: 2017.25 | Q8: 2017.5 | R8: 2017.75 | S8: 2018 | T8: 2018.25 | U8: 2018.5 | V8: 2018.75 | W8: 2019 | X8: 2019.25 | Y8: 2019.5 | Z8: 2019.75 | AA8: 2020 | AB8: 2020.25 | AC8: 2020.5 | AD8: 2020.75 | AE8: 2021 | AF8: 2021.25 | AG8: 2021.5 | AH8: 2021.75 | AI8: 2022 | AJ8: 2022.25 | AK8: 2022.5 | AL8: 2022.75 | AM8: 2023 | AN8: 2023.25 | AO8: 2023.5 | AP8: 2023.75 | AQ8: 2024 | AR8: 2024.25 | AS8: 2024.5 | AT8: 2024.75 | AU8: 2025 | AV8: 2025.25 | AW8: 2025.5 | AX8: 2025.75 | AY8: 2026 | AZ8: 2026.25 | BA8: 2026.5 | BB8: 2026.75 | BC8: 2027 | BD8: 2027.25 | BE8: 2027.5 | BF8: 2027.75 | BG8: 2028 | BH8: 2028.25 | BI8: 2028.5 | BJ8: 2028.75 | BK8: 2029 | BL8: 2029.25 | BM8: 2029.5 | BN8: 2029.75 | BO8: 2030 | BP8: 2030.25 | BQ8: 2030.5 | BR8: 2030.75 | BS8: 2031 | BT8: 2031.25 | BU8: 2031.5 | BV8: 2031.75 | BW8: 2032 | BX8: 2032.25 | BY8: 2032.5 | BZ8: 2032.75 | CA8: 2033 | CB8: 2033.25 | CC8: 2033.5 | CD8: 2033.75 | CE8: 2034 | CF8: 2034.25 | CG8: 2034.5 | CH8: 2034.75 | CI8: 2035 | CJ8: 2035.25 | CK8: 2035.5 | CL8: 2035.75 | CM8: 2036 | CN8: 2036.25 | CO8: 2036.5 | CP8: 2036.75 | CQ8: 2037 | CR8: 2037.25 | CS8: 2037.5 | CT8: 2037.75 | CU8: 2038 | CV8: 2038.25 | CW8: 2038.5 | CX8: 2038.75 | CY8: 2039 | CZ8: 2039.25 | DA8: 2039.5 | DB8: 2039.75 | DC8: 2040 | DD8: 2040.25 | DE8: 2040.5 | DF8: 2040.75 | DG8: 2041 | DH8: 2041.25 | DI8: 2041.5 | DJ8: 2041.75 | DK8: 2042 | DL8: 2042.25 | DM8: 2042.5 | DN8: 2042.75 | DO8: 2043 | DP8: 2043.25 | DQ8: 2043.5 | DR8: 2043.75 | DS8: 2044 | DT8: 2044.25 | DU8: 2044.5 | DV8: 2044.75 | DW8: 2045 | DX8: 2045.25 | DY8: 2045.5 | DZ8: 2045.75 | EA8: 2046 | EB8: 2046.25 | EC8: 2046.5 | ED8: 2046.75 | EE8: 2047 | EF8: 2047.25 | EG8: 2047.5 | EH8: 2047.75 | EI8: 2048 | EJ8: 2048.25 | EK8: 2048.5 | EL8: 2048.75 | EM8: 2049 | EN8: 2049.25 | EO8: 2049.5 | EP8: 2049.75 | EQ8: 2050 | ER8: 2050.25 | ES8: 2050.5 | ET8: 2050.75 | EU8: 2051 | EV8: 2051.25 | EW8: 2051.5 | EX8: 2051.75
A9: Annual spend | C9: $/year | F9: OR | G9: 1e+15 | H9: 1e+15 | I9: 1e+15 | J9: 1e+15 | K9: 1e+15 | L9: 1e+15 | M9: 1e+15 | N9: 1e+15 | O9: 1e+15 | P9: 1e+15 | Q9: 1e+15 | R9: 1e+15 | S9: 1e+15 | T9: 1e+15 | U9: 1e+15 | V9: 1e+15 | W9: 1e+15 | X9: 1e+15 | Y9: 1e+15 | Z9: 1e+15 | AA9: 1e+15 | AB9: 1e+15 | AC9: 1e+15 | AD9: 1e+15 | AE9: 1e+15 | AF9: 1e+15 | AG9: 1e+15 | AH9: 1e+15 | AI9: 1e+15 | AJ9: 1e+15 | AK9: 1e+15 | AL9: 1e+15 | AM9: 1e+15 | AN9: 1e+15 | AO9: 1e+15 | AP9: 1e+15 | AQ9: 1e+15 | AR9: 1e+15 | AS9: 1e+15 | AT9: 1e+15 | AU9: 1e+15 | AV9: 1e+15 | AW9: 1e+15 | AX9: 1e+15 | AY9: 1e+15 | AZ9: 1e+15 | BA9: 1e+15 | BB9: 1e+15 | BC9: 1e+15 | BD9: 1e+15 | BE9: 1e+15 | BF9: 1e+15 | BG9: 1e+15 | BH9: 1e+15 | BI9: 1e+15 | BJ9: 1e+15 | BK9: 1e+15 | BL9: 1e+15 | BM9: 1e+15 | BN9: 1e+15 | BO9: 1e+15 | BP9: 1e+15 | BQ9: 1e+15 | BR9: 1e+15 | BS9: 1e+15 | BT9: 1e+15 | BU9: 1e+15 | BV9: 1e+15 | BW9: 1e+15 | BX9: 1e+15 | BY9: 1e+15 | BZ9: 1e+15 | CA9: 1e+15 | CB9: 1e+15 | CC9: 1e+15 | CD9: 1e+15 | CE9: 1e+15 | CF9: 1e+15 | CG9: 1e+15 | CH9: 1e+15 | CI9: 1e+15 | CJ9: 1e+15 | CK9: 1e+15 | CL9: 1e+15 | CM9: 1e+15 | CN9: 1e+15 | CO9: 1e+15 | CP9: 1e+15 | CQ9: 1e+15 | CR9: 1e+15 | CS9: 1e+15 | CT9: 1e+15 | CU9: 1e+15 | CV9: 1e+15 | CW9: 1e+15 | CX9: 1e+15 | CY9: 1e+15 | CZ9: 1e+15 | DA9: 1e+15 | DB9: 1e+15 | DC9: 1e+15 | DD9: 1e+15 | DE9: 1e+15 | DF9: 1e+15 | DG9: 1e+15 | DH9: 1e+15 | DI9: 1e+15 | DJ9: 1e+15 | DK9: 1e+15 | DL9: 1e+15 | DM9: 1e+15 | DN9: 1e+15 | DO9: 1e+15 | DP9: 1e+15 | DQ9: 1e+15 | DR9: 1e+15 | DS9: 1e+15 | DT9: 1e+15 | DU9: 1e+15 | DV9: 1e+15 | DW9: 1e+15 | DX9: 1e+15 | DY9: 1e+15 | DZ9: 1e+15 | EA9: 1e+15 | EB9: 1e+15 | EC9: 1e+15 | ED9: 1e+15 | EE9: 1e+15 | EF9: 1e+15 | EG9: 1e+15 | EH9: 1e+15 | EI9: 1e+15 | EJ9: 1e+15 | EK9: 1e+15 | EL9: 1e+15 | EM9: 1e+15 | EN9: 1e+15 | EO9: 1e+15 | EP9: 1e+15 | EQ9: 1e+15 | ER9: 1e+15 | ES9: 1e+15 | ET9: 1e+15 | EU9: 1e+15 | EV9: 1e+15 | EW9: 1e+15 | EX9: 1e+15
A10: Unit cost | C10: $/person | F10: OR | G10: 23.847312 | H10: 23.847312 | I10: 23.847312 | J10: 23.847312 | K10: 23.847312 | L10: 23.847312 | M10: 23.847312 | N10: 23.847312 | O10: 23.847312 | P10: 23.847312 | Q10: 23.847312 | R10: 23.847312 | S10: 23.847312 | T10: 23.847312 | U10: 23.847312 | V10: 23.847312 | W10: 23.847312 | X10: 23.847312 | Y10: 23.847312 | Z10: 23.847312 | AA10: 23.847312 | AB10: 23.847312 | AC10: 23.847312 | AD10: 23.847312 | AE10: 23.847312 | AF10: 23.847312 | AG10: 23.847312 | AH10: 23.847312 | AI10: 23.847312 | AJ10: 23.847312 | AK10: 23.847312 | AL10: 23.847312 | AM10: 23.847312 | AN10: 23.847312 | AO10: 23.847312 | AP10: 23.847312 | AQ10: 23.847312 | AR10: 23.847312 | AS10: 23.847312 | AT10: 23.847312 | AU10: 23.847312 | AV10: 23.847312 | AW10: 23.847312 | AX10: 23.847312 | AY10: 23.847312 | AZ10: 23.847312 | BA10: 23.847312 | BB10: 23.847312 | BC10: 23.847312 | BD10: 23.847312 | BE10: 23.847312 | BF10: 23.847312 | BG10: 23.847312 | BH10: 23.847312 | BI10: 23.847312 | BJ10: 23.847312 | BK10: 23.847312 | BL10: 23.847312 | BM10: 23.847312 | BN10: 23.847312 | BO10: 23.847312 | BP10: 23.847312 | BQ10: 23.847312 | BR10: 23.847312 | BS10: 23.847312 | BT10: 23.847312 | BU10: 23.847312 | BV10: 23.847312 | BW10: 23.847312 | BX10: 23.847312 | BY10: 23.847312 | BZ10: 23.847312 | CA10: 23.847312 | CB10: 23.847312 | CC10: 23.847312 | CD10: 23.847312 | CE10: 23.847312 | CF10: 23.847312 | CG10: 23.847312 | CH10: 23.847312 | CI10: 23.847312 | CJ10: 23.847312 | CK10: 23.847312 | CL10: 23.847312 | CM10: 23.847312 | CN10: 23.847312 | CO10: 23.847312 | CP10: 23.847312 | CQ10: 23.847312 | CR10: 23.847312 | CS10: 23.847312 | CT10: 23.847312 | CU10: 23.847312 | CV10: 23.847312 | CW10: 23.847312 | CX10: 23.847312 | CY10: 23.847312 | CZ10: 23.847312 | DA10: 23.847312 | DB10: 23.847312 | DC10: 23.847312 | DD10: 23.847312 | DE10: 23.847312 | DF10: 23.847312 | DG10: 23.847312 | DH10: 23.847312 | DI10: 23.847312 | DJ10: 23.847312 | DK10: 23.847312 | DL10: 23.847312 | DM10: 23.847312 | DN10: 23.847312 | DO10: 23.847312 | DP10: 23.847312 | DQ10: 23.847312 | DR10: 23.847312 | DS10: 23.847312 | DT10: 23.847312 | DU10: 23.847312 | DV10: 23.847312 | DW10: 23.847312 | DX10: 23.847312 | DY10: 23.847312 | DZ10: 23.847312 | EA10: 23.847312 | EB10: 23.847312 | EC10: 23.847312 | ED10: 23.847312 | EE10: 23.847312 | EF10: 23.847312 | EG10: 23.847312 | EH10: 23.847312 | EI10: 23.847312 | EJ10: 23.847312 | EK10: 23.847312 | EL10: 23.847312 | EM10: 23.847312 | EN10: 23.847312 | EO10: 23.847312 | EP10: 23.847312 | EQ10: 23.847312 | ER10: 23.847312 | ES10: 23.847312 | ET10: 23.847312 | EU10: 23.847312 | EV10: 23.847312 | EW10: 23.847312 | EX10: 23.847312
A11: Capacity constraint | C11: people/year | F11: OR
A12: Saturation | C12: N.A. | F12: OR
A13: Coverage | C13: people/year | E13: 100000 | F13: OR
A15: ='Program targeting'!$B$5 -> soc_rutf_hospitalized_19-59_wasting_hm | B15: Provenance | C15: Units | D15: Uncertainty | E15: Assumption | G15: 2015 | H15: 2015.25 | I15: 2015.5 | J15: 2015.75 | K15: 2016 | L15: 2016.25 | M15: 2016.5 | N15: 2016.75 | O15: 2017 | P15: 2017.25 | Q15: 2017.5 | R15: 2017.75 | S15: 2018 | T15: 2018.25 | U15: 2018.5 | V15: 2018.75 | W15: 2019 | X15: 2019.25 | Y15: 2019.5 | Z15: 2019.75 | AA15: 2020 | AB15: 2020.25 | AC15: 2020.5 | AD15: 2020.75 | AE15: 2021 | AF15: 2021.25 | AG15: 2021.5 | AH15: 2021.75 | AI15: 2022 | AJ15: 2022.25 | AK15: 2022.5 | AL15: 2022.75 | AM15: 2023 | AN15: 2023.25 | AO15: 2023.5 | AP15: 2023.75 | AQ15: 2024 | AR15: 2024.25 | AS15: 2024.5 | AT15: 2024.75 | AU15: 2025 | AV15: 2025.25 | AW15: 2025.5 | AX15: 2025.75 | AY15: 2026 | AZ15: 2026.25 | BA15: 2026.5 | BB15: 2026.75 | BC15: 2027 | BD15: 2027.25 | BE15: 2027.5 | BF15: 2027.75 | BG15: 2028 | BH15: 2028.25 | BI15: 2028.5 | BJ15: 2028.75 | BK15: 2029 | BL15: 2029.25 | BM15: 2029.5 | BN15: 2029.75 | BO15: 2030 | BP15: 2030.25 | BQ15: 2030.5 | BR15: 2030.75 | BS15: 2031 | BT15: 2031.25 | BU15: 2031.5 | BV15: 2031.75 | BW15: 2032 | BX15: 2032.25 | BY15: 2032.5 | BZ15: 2032.75 | CA15: 2033 | CB15: 2033.25 | CC15: 2033.5 | CD15: 2033.75 | CE15: 2034 | CF15: 2034.25 | CG15: 2034.5 | CH15: 2034.75 | CI15: 2035 | CJ15: 2035.25 | CK15: 2035.5 | CL15: 2035.75 | CM15: 2036 | CN15: 2036.25 | CO15: 2036.5 | CP15: 2036.75 | CQ15: 2037 | CR15: 2037.25 | CS15: 2037.5 | CT15: 2037.75 | CU15: 2038 | CV15: 2038.25 | CW15: 2038.5 | CX15: 2038.75 | CY15: 2039 | CZ15: 2039.25 | DA15: 2039.5 | DB15: 2039.75 | DC15: 2040 | DD15: 2040.25 | DE15: 2040.5 | DF15: 2040.75 | DG15: 2041 | DH15: 2041.25 | DI15: 2041.5 | DJ15: 2041.75 | DK15: 2042 | DL15: 2042.25 | DM15: 2042.5 | DN15: 2042.75 | DO15: 2043 | DP15: 2043.25 | DQ15: 2043.5 | DR15: 2043.75 | DS15: 2044 | DT15: 2044.25 | DU15: 2044.5 | DV15: 2044.75 | DW15: 2045 | DX15: 2045.25 | DY15: 2045.5 | DZ15: 2045.75 | EA15: 2046 | EB15: 2046.25 | EC15: 2046.5 | ED15: 2046.75 | EE15: 2047 | EF15: 2047.25 | EG15: 2047.5 | EH15: 2047.75 | EI15: 2048 | EJ15: 2048.25 | EK15: 2048.5 | EL15: 2048.75 | EM15: 2049 | EN15: 2049.25 | EO15: 2049.5 | EP15: 2049.75 | EQ15: 2050 | ER15: 2050.25 | ES15: 2050.5 | ET15: 2050.75 | EU15: 2051 | EV15: 2051.25 | EW15: 2051.5 | EX15: 2051.75
A16: Annual spend | C16: $/year | F16: OR | G16: 1e+15 | H16: 1e+15 | I16: 1e+15 | J16: 1e+15 | K16: 1e+15 | L16: 1e+15 | M16: 1e+15 | N16: 1e+15 | O16: 1e+15 | P16: 1e+15 | Q16: 1e+15 | R16: 1e+15 | S16: 1e+15 | T16: 1e+15 | U16: 1e+15 | V16: 1e+15 | W16: 1e+15 | X16: 1e+15 | Y16: 1e+15 | Z16: 1e+15 | AA16: 1e+15 | AB16: 1e+15 | AC16: 1e+15 | AD16: 1e+15 | AE16: 1e+15 | AF16: 1e+15 | AG16: 1e+15 | AH16: 1e+15 | AI16: 1e+15 | AJ16: 1e+15 | AK16: 1e+15 | AL16: 1e+15 | AM16: 1e+15 | AN16: 1e+15 | AO16: 1e+15 | AP16: 1e+15 | AQ16: 1e+15 | AR16: 1e+15 | AS16: 1e+15 | AT16: 1e+15 | AU16: 1e+15 | AV16: 1e+15 | AW16: 1e+15 | AX16: 1e+15 | AY16: 1e+15 | AZ16: 1e+15 | BA16: 1e+15 | BB16: 1e+15 | BC16: 1e+15 | BD16: 1e+15 | BE16: 1e+15 | BF16: 1e+15 | BG16: 1e+15 | BH16: 1e+15 | BI16: 1e+15 | BJ16: 1e+15 | BK16: 1e+15 | BL16: 1e+15 | BM16: 1e+15 | BN16: 1e+15 | BO16: 1e+15 | BP16: 1e+15 | BQ16: 1e+15 | BR16: 1e+15 | BS16: 1e+15 | BT16: 1e+15 | BU16: 1e+15 | BV16: 1e+15 | BW16: 1e+15 | BX16: 1e+15 | BY16: 1e+15 | BZ16: 1e+15 | CA16: 1e+15 | CB16: 1e+15 | CC16: 1e+15 | CD16: 1e+15 | CE16: 1e+15 | CF16: 1e+15 | CG16: 1e+15 | CH16: 1e+15 | CI16: 1e+15 | CJ16: 1e+15 | CK16: 1e+15 | CL16: 1e+15 | CM16: 1e+15 | CN16: 1e+15 | CO16: 1e+15 | CP16: 1e+15 | CQ16: 1e+15 | CR16: 1e+15 | CS16: 1e+15 | CT16: 1e+15 | CU16: 1e+15 | CV16: 1e+15 | CW16: 1e+15 | CX16: 1e+15 | CY16: 1e+15 | CZ16: 1e+15 | DA16: 1e+15 | DB16: 1e+15 | DC16: 1e+15 | DD16: 1e+15 | DE16: 1e+15 | DF16: 1e+15 | DG16: 1e+15 | DH16: 1e+15 | DI16: 1e+15 | DJ16: 1e+15 | DK16: 1e+15 | DL16: 1e+15 | DM16: 1e+15 | DN16: 1e+15 | DO16: 1e+15 | DP16: 1e+15 | DQ16: 1e+15 | DR16: 1e+15 | DS16: 1e+15 | DT16: 1e+15 | DU16: 1e+15 | DV16: 1e+15 | DW16: 1e+15 | DX16: 1e+15 | DY16: 1e+15 | DZ16: 1e+15 | EA16: 1e+15 | EB16: 1e+15 | EC16: 1e+15 | ED16: 1e+15 | EE16: 1e+15 | EF16: 1e+15 | EG16: 1e+15 | EH16: 1e+15 | EI16: 1e+15 | EJ16: 1e+15 | EK16: 1e+15 | EL16: 1e+15 | EM16: 1e+15 | EN16: 1e+15 | EO16: 1e+15 | EP16: 1e+15 | EQ16: 1e+15 | ER16: 1e+15 | ES16: 1e+15 | ET16: 1e+15 | EU16: 1e+15 | EV16: 1e+15 | EW16: 1e+15 | EX16: 1e+15
A17: Unit cost | C17: $/person | F17: OR | G17: 23.847312 | H17: 23.847312 | I17: 23.847312 | J17: 23.847312 | K17: 23.847312 | L17: 23.847312 | M17: 23.847312 | N17: 23.847312 | O17: 23.847312 | P17: 23.847312 | Q17: 23.847312 | R17: 23.847312 | S17: 23.847312 | T17: 23.847312 | U17: 23.847312 | V17: 23.847312 | W17: 23.847312 | X17: 23.847312 | Y17: 23.847312 | Z17: 23.847312 | AA17: 23.847312 | AB17: 23.847312 | AC17: 23.847312 | AD17: 23.847312 | AE17: 23.847312 | AF17: 23.847312 | AG17: 23.847312 | AH17: 23.847312 | AI17: 23.847312 | AJ17: 23.847312 | AK17: 23.847312 | AL17: 23.847312 | AM17: 23.847312 | AN17: 23.847312 | AO17: 23.847312 | AP17: 23.847312 | AQ17: 23.847312 | AR17: 23.847312 | AS17: 23.847312 | AT17: 23.847312 | AU17: 23.847312 | AV17: 23.847312 | AW17: 23.847312 | AX17: 23.847312 | AY17: 23.847312 | AZ17: 23.847312 | BA17: 23.847312 | BB17: 23.847312 | BC17: 23.847312 | BD17: 23.847312 | BE17: 23.847312 | BF17: 23.847312 | BG17: 23.847312 | BH17: 23.847312 | BI17: 23.847312 | BJ17: 23.847312 | BK17: 23.847312 | BL17: 23.847312 | BM17: 23.847312 | BN17: 23.847312 | BO17: 23.847312 | BP17: 23.847312 | BQ17: 23.847312 | BR17: 23.847312 | BS17: 23.847312 | BT17: 23.847312 | BU17: 23.847312 | BV17: 23.847312 | BW17: 23.847312 | BX17: 23.847312 | BY17: 23.847312 | BZ17: 23.847312 | CA17: 23.847312 | CB17: 23.847312 | CC17: 23.847312 | CD17: 23.847312 | CE17: 23.847312 | CF17: 23.847312 | CG17: 23.847312 | CH17: 23.847312 | CI17: 23.847312 | CJ17: 23.847312 | CK17: 23.847312 | CL17: 23.847312 | CM17: 23.847312 | CN17: 23.847312 | CO17: 23.847312 | CP17: 23.847312 | CQ17: 23.847312 | CR17: 23.847312 | CS17: 23.847312 | CT17: 23.847312 | CU17: 23.847312 | CV17: 23.847312 | CW17: 23.847312 | CX17: 23.847312 | CY17: 23.847312 | CZ17: 23.847312 | DA17: 23.847312 | DB17: 23.847312 | DC17: 23.847312 | DD17: 23.847312 | DE17: 23.847312 | DF17: 23.847312 | DG17: 23.847312 | DH17: 23.847312 | DI17: 23.847312 | DJ17: 23.847312 | DK17: 23.847312 | DL17: 23.847312 | DM17: 23.847312 | DN17: 23.847312 | DO17: 23.847312 | DP17: 23.847312 | DQ17: 23.847312 | DR17: 23.847312 | DS17: 23.847312 | DT17: 23.847312 | DU17: 23.847312 | DV17: 23.847312 | DW17: 23.847312 | DX17: 23.847312 | DY17: 23.847312 | DZ17: 23.847312 | EA17: 23.847312 | EB17: 23.847312 | EC17: 23.847312 | ED17: 23.847312 | EE17: 23.847312 | EF17: 23.847312 | EG17: 23.847312 | EH17: 23.847312 | EI17: 23.847312 | EJ17: 23.847312 | EK17: 23.847312 | EL17: 23.847312 | EM17: 23.847312 | EN17: 23.847312 | EO17: 23.847312 | EP17: 23.847312 | EQ17: 23.847312 | ER17: 23.847312 | ES17: 23.847312 | ET17: 23.847312 | EU17: 23.847312 | EV17: 23.847312 | EW17: 23.847312 | EX17: 23.847312
